[
  {
    "url": "https://api.github.com/repos/jupyter/notebook/issues/comments/391329952",
    "html_url": "https://github.com/jupyter/notebook/issues/3633#issuecomment-391329952",
    "issue_url": "https://api.github.com/repos/jupyter/notebook/issues/3633",
    "id": 391329952,
    "node_id": "MDEyOklzc3VlQ29tbWVudDM5MTMyOTk1Mg==",
    "user": {
      "login": "takluyver",
      "id": 327925,
      "node_id": "MDQ6VXNlcjMyNzkyNQ==",
      "avatar_url": "https://avatars.githubusercontent.com/u/327925?v=4",
      "gravatar_id": "",
      "url": "https://api.github.com/users/takluyver",
      "html_url": "https://github.com/takluyver",
      "followers_url": "https://api.github.com/users/takluyver/followers",
      "following_url": "https://api.github.com/users/takluyver/following{/other_user}",
      "gists_url": "https://api.github.com/users/takluyver/gists{/gist_id}",
      "starred_url": "https://api.github.com/users/takluyver/starred{/owner}{/repo}",
      "subscriptions_url": "https://api.github.com/users/takluyver/subscriptions",
      "organizations_url": "https://api.github.com/users/takluyver/orgs",
      "repos_url": "https://api.github.com/users/takluyver/repos",
      "events_url": "https://api.github.com/users/takluyver/events{/privacy}",
      "received_events_url": "https://api.github.com/users/takluyver/received_events",
      "type": "User",
      "site_admin": false
    },
    "created_at": "2018-05-23T12:34:20Z",
    "updated_at": "2018-05-23T12:34:20Z",
    "author_association": "MEMBER",
    "body": "Notebook 5.5 doesn't strictly need pyzmq 17, but older versions of pyzmq don't work with tornado 5 - but there's no way to express that relationship, because neither of pyzmq and tornado depend on each other. After a while of fielding bug reports from people who had updated tornado and not pyzmq, we decided to add the requirement so they'd get a new version of pyzmq automatically.\r\n\r\nDoes Fedora already have tornado 5? If not, it might be worth updating that. If that's not it, I don't really know.",
    "performed_via_github_app": null
  },
  {
    "url": "https://api.github.com/repos/jupyter/notebook/issues/comments/391331405",
    "html_url": "https://github.com/jupyter/notebook/issues/3633#issuecomment-391331405",
    "issue_url": "https://api.github.com/repos/jupyter/notebook/issues/3633",
    "id": 391331405,
    "node_id": "MDEyOklzc3VlQ29tbWVudDM5MTMzMTQwNQ==",
    "user": {
      "login": "hroncok",
      "id": 2401856,
      "node_id": "MDQ6VXNlcjI0MDE4NTY=",
      "avatar_url": "https://avatars.githubusercontent.com/u/2401856?v=4",
      "gravatar_id": "",
      "url": "https://api.github.com/users/hroncok",
      "html_url": "https://github.com/hroncok",
      "followers_url": "https://api.github.com/users/hroncok/followers",
      "following_url": "https://api.github.com/users/hroncok/following{/other_user}",
      "gists_url": "https://api.github.com/users/hroncok/gists{/gist_id}",
      "starred_url": "https://api.github.com/users/hroncok/starred{/owner}{/repo}",
      "subscriptions_url": "https://api.github.com/users/hroncok/subscriptions",
      "organizations_url": "https://api.github.com/users/hroncok/orgs",
      "repos_url": "https://api.github.com/users/hroncok/repos",
      "events_url": "https://api.github.com/users/hroncok/events{/privacy}",
      "received_events_url": "https://api.github.com/users/hroncok/received_events",
      "type": "User",
      "site_admin": false
    },
    "created_at": "2018-05-23T12:39:34Z",
    "updated_at": "2018-05-23T12:43:11Z",
    "author_association": "CONTRIBUTOR",
    "body": "That's not the issue.\r\n\r\n```\r\npython3                           x86_64 3.6.5-4.fc29    \r\npython3-babel                     noarch 2.5.1-2.fc28            \r\npython3-backcall                  noarch 0.1.0-1.fc29            \r\npython3-bleach                    noarch 2.1.3-1.fc29            \r\npython3-dateutil                  noarch 1:2.7.0-1.fc29\r\npython3-decorator                 noarch 4.2.1-1.fc28            \r\npython3-defusedxml                noarch 0.5.0-4.fc29            \r\npython3-devel                     x86_64 3.6.5-4.fc29  \r\npython3-docutils                  noarch 0.14-3.fc28             \r\npython3-entrypoints               noarch 0.2.3-5.fc28            \r\npython3-funcsigs                  noarch 1.0.2-9.fc29            \r\npython3-html5lib                  noarch 1:0.999999999-6.fc29    \r\npython3-chardet                   noarch 3.0.4-5.fc29            \r\npython3-idna                      noarch 2.5-4.fc28              \r\npython3-imagesize                 noarch 1.0.0-1.fc29            \r\npython3-ipykernel                 noarch 4.6.0-4.fc28  \r\npython3-ipython_genutils          noarch 0.1.0-12.fc29 \r\npython3-ipython                   noarch 6.4.0-1.fc29            \r\npython3-ipython-sphinx            noarch 6.4.0-1.fc29  \r\npython3-jedi                      noarch 0.12.0-1.fc29           \r\npython3-jinja2                    noarch 2.10-2.fc28             \r\npython3-jsonschema                noarch 2.6.0-4.fc29            \r\npython3-jupyter-client            noarch 5.2.3-1.fc29  \r\npython3-jupyter-core              noarch 4.4.0-2.fc28  \r\npython3-markupsafe                x86_64 0.23-17.fc28            \r\npython3-mistune                   x86_64 0.8.3-3.fc28            \r\npython3-mock                      noarch 2.0.0-8.fc29            \r\npython3-nbconvert                 noarch 5.3.1-7.fc29  \r\npython3-nbformat                  noarch 4.4.0-2.fc28  \r\npython3-nbsphinx                  noarch 0.2.17-2.fc28 \r\npython3-nose-exclude              noarch 0.4.1-11.fc29 \r\npython3-nose                      noarch 1.3.7-19.fc28 \r\npython3-nose_warnings_filters     noarch 0.1.5-4.fc28  \r\npython3-packaging                 noarch 16.8-8.fc29             \r\npython3-pandocfilters             noarch 1.4.1-3.fc28  \r\npython3-parso                     noarch 0.2.1-1.fc29            \r\npython3-pbr                       noarch 3.1.1-7.fc29            \r\npython3-pexpect                   noarch 4.4-1.fc29              \r\npython3-pickleshare               noarch 0.7.4-8.fc28            \r\npython3-pip                       noarch 9.0.3-2.fc29            \r\npython3-prompt_toolkit            noarch 1.0.14-5.fc29           \r\npython3-ptyprocess                noarch 0.5.2-3.fc28            \r\npython3-pycurl                    x86_64 7.43.0-15.fc29          \r\npython3-pygments                  noarch 2.2.0-11.fc29           \r\npython3-pyparsing                 noarch 2.1.10-7.fc29           \r\npython3-pysocks                   noarch 1.6.8-2.fc28            \r\npython3-pytz                      noarch 2017.2-7.fc29           \r\npython3-requests                  noarch 2.18.4-4.fc29           \r\npython3-rpm-generators            noarch 5-1.fc28                \r\npython3-rpm-macros                noarch 3-29.fc29               \r\npython3-send2trash                noarch 1.4.2-4.fc28  \r\npython3-setuptools                noarch 39.0.1-1.fc29 \r\npython3-simplegeneric             noarch 0.8.1-9.fc29            \r\npython3-six                       noarch 1.11.0-3.fc28           \r\npython3-snowballstemmer           noarch 1.2.1-5.fc28            \r\npython3-sphinxcontrib-websupport  noarch 1.0.1-8.20180316git.fc29\r\npython3-sphinx                    noarch 1:1.7.2-2.fc29\r\npython3-sphinx_rtd_theme          noarch 0.3.1-1.fc29  \r\npython3-sphinx-theme-alabaster    noarch 0.7.9-6.fc28            \r\npython3-sqlalchemy                x86_64 1.2.7-1.fc29            \r\npython3-terminado                 noarch 0.8.1-2.fc28  \r\npython3-testpath                  noarch 0.3.1-3.fc28  \r\npython3-tornado                   x86_64 5.0.2-2.fc29  \r\npython3-traitlets                 noarch 4.3.2-5.fc29\r\npython3-urllib3                   noarch 1.22-9.fc29             \r\npython3-wcwidth                   noarch 0.1.7-6.fc29            \r\npython3-webencodings              noarch 0.5.1-4.fc28            \r\npython3-whoosh                    noarch 2.7.4-9.fc29                    \r\npython3-zmq                       x86_64 17.0.0-1.fc29           \r\n```\r\n\r\n",
    "performed_via_github_app": null
  },
  {
    "url": "https://api.github.com/repos/jupyter/notebook/issues/comments/391371314",
    "html_url": "https://github.com/jupyter/notebook/issues/3633#issuecomment-391371314",
    "issue_url": "https://api.github.com/repos/jupyter/notebook/issues/3633",
    "id": 391371314,
    "node_id": "MDEyOklzc3VlQ29tbWVudDM5MTM3MTMxNA==",
    "user": {
      "login": "minrk",
      "id": 151929,
      "node_id": "MDQ6VXNlcjE1MTkyOQ==",
      "avatar_url": "https://avatars.githubusercontent.com/u/151929?v=4",
      "gravatar_id": "",
      "url": "https://api.github.com/users/minrk",
      "html_url": "https://github.com/minrk",
      "followers_url": "https://api.github.com/users/minrk/followers",
      "following_url": "https://api.github.com/users/minrk/following{/other_user}",
      "gists_url": "https://api.github.com/users/minrk/gists{/gist_id}",
      "starred_url": "https://api.github.com/users/minrk/starred{/owner}{/repo}",
      "subscriptions_url": "https://api.github.com/users/minrk/subscriptions",
      "organizations_url": "https://api.github.com/users/minrk/orgs",
      "repos_url": "https://api.github.com/users/minrk/repos",
      "events_url": "https://api.github.com/users/minrk/events{/privacy}",
      "received_events_url": "https://api.github.com/users/minrk/received_events",
      "type": "User",
      "site_admin": false
    },
    "created_at": "2018-05-23T14:37:42Z",
    "updated_at": "2018-05-23T14:37:42Z",
    "author_association": "MEMBER",
    "body": "I suspect the runtime error is mostly a red herring, since it's generally an indication of failure to cleanup after an already failing test, rather than an indication of failure itself.\r\n\r\nThe package list does show that ipykernel is 4.6.0. Latest is 4.8.3, and I think at least 4.8.0 is required to work with tornado 5. This is likely relevant, as the first test that fails is talking to the kernel API.",
    "performed_via_github_app": null
  },
  {
    "url": "https://api.github.com/repos/jupyter/notebook/issues/comments/391383124",
    "html_url": "https://github.com/jupyter/notebook/issues/3633#issuecomment-391383124",
    "issue_url": "https://api.github.com/repos/jupyter/notebook/issues/3633",
    "id": 391383124,
    "node_id": "MDEyOklzc3VlQ29tbWVudDM5MTM4MzEyNA==",
    "user": {
      "login": "hroncok",
      "id": 2401856,
      "node_id": "MDQ6VXNlcjI0MDE4NTY=",
      "avatar_url": "https://avatars.githubusercontent.com/u/2401856?v=4",
      "gravatar_id": "",
      "url": "https://api.github.com/users/hroncok",
      "html_url": "https://github.com/hroncok",
      "followers_url": "https://api.github.com/users/hroncok/followers",
      "following_url": "https://api.github.com/users/hroncok/following{/other_user}",
      "gists_url": "https://api.github.com/users/hroncok/gists{/gist_id}",
      "starred_url": "https://api.github.com/users/hroncok/starred{/owner}{/repo}",
      "subscriptions_url": "https://api.github.com/users/hroncok/subscriptions",
      "organizations_url": "https://api.github.com/users/hroncok/orgs",
      "repos_url": "https://api.github.com/users/hroncok/repos",
      "events_url": "https://api.github.com/users/hroncok/events{/privacy}",
      "received_events_url": "https://api.github.com/users/hroncok/received_events",
      "type": "User",
      "site_admin": false
    },
    "created_at": "2018-05-23T15:09:09Z",
    "updated_at": "2018-05-23T15:09:09Z",
    "author_association": "CONTRIBUTOR",
    "body": "Thank you for the pointer. Let me try to update ipykernel.",
    "performed_via_github_app": null
  },
  {
    "url": "https://api.github.com/repos/jupyter/notebook/issues/comments/391511857",
    "html_url": "https://github.com/jupyter/notebook/issues/3633#issuecomment-391511857",
    "issue_url": "https://api.github.com/repos/jupyter/notebook/issues/3633",
    "id": 391511857,
    "node_id": "MDEyOklzc3VlQ29tbWVudDM5MTUxMTg1Nw==",
    "user": {
      "login": "hroncok",
      "id": 2401856,
      "node_id": "MDQ6VXNlcjI0MDE4NTY=",
      "avatar_url": "https://avatars.githubusercontent.com/u/2401856?v=4",
      "gravatar_id": "",
      "url": "https://api.github.com/users/hroncok",
      "html_url": "https://github.com/hroncok",
      "followers_url": "https://api.github.com/users/hroncok/followers",
      "following_url": "https://api.github.com/users/hroncok/following{/other_user}",
      "gists_url": "https://api.github.com/users/hroncok/gists{/gist_id}",
      "starred_url": "https://api.github.com/users/hroncok/starred{/owner}{/repo}",
      "subscriptions_url": "https://api.github.com/users/hroncok/subscriptions",
      "organizations_url": "https://api.github.com/users/hroncok/orgs",
      "repos_url": "https://api.github.com/users/hroncok/repos",
      "events_url": "https://api.github.com/users/hroncok/events{/privacy}",
      "received_events_url": "https://api.github.com/users/hroncok/received_events",
      "type": "User",
      "site_admin": false
    },
    "created_at": "2018-05-23T22:06:56Z",
    "updated_at": "2018-05-23T22:06:56Z",
    "author_association": "CONTRIBUTOR",
    "body": "ipykernel 4.8.2 solves the problem, but gets me another one:\r\n\r\n    OSError: [Errno 18] Invalid cross-device link: b'/tmp/tmpafzr1m5y/notebooks/foo/z.ipynb' -> b'/builddir/.local/share/Trash/files/z.ipynb'",
    "performed_via_github_app": null
  },
  {
    "url": "https://api.github.com/repos/jupyter/notebook/issues/comments/391518365",
    "html_url": "https://github.com/jupyter/notebook/issues/3633#issuecomment-391518365",
    "issue_url": "https://api.github.com/repos/jupyter/notebook/issues/3633",
    "id": 391518365,
    "node_id": "MDEyOklzc3VlQ29tbWVudDM5MTUxODM2NQ==",
    "user": {
      "login": "hroncok",
      "id": 2401856,
      "node_id": "MDQ6VXNlcjI0MDE4NTY=",
      "avatar_url": "https://avatars.githubusercontent.com/u/2401856?v=4",
      "gravatar_id": "",
      "url": "https://api.github.com/users/hroncok",
      "html_url": "https://github.com/hroncok",
      "followers_url": "https://api.github.com/users/hroncok/followers",
      "following_url": "https://api.github.com/users/hroncok/following{/other_user}",
      "gists_url": "https://api.github.com/users/hroncok/gists{/gist_id}",
      "starred_url": "https://api.github.com/users/hroncok/starred{/owner}{/repo}",
      "subscriptions_url": "https://api.github.com/users/hroncok/subscriptions",
      "organizations_url": "https://api.github.com/users/hroncok/orgs",
      "repos_url": "https://api.github.com/users/hroncok/repos",
      "events_url": "https://api.github.com/users/hroncok/events{/privacy}",
      "received_events_url": "https://api.github.com/users/hroncok/received_events",
      "type": "User",
      "site_admin": false
    },
    "created_at": "2018-05-23T22:32:30Z",
    "updated_at": "2018-05-23T22:32:30Z",
    "author_association": "CONTRIBUTOR",
    "body": "Note that this only occurs on my computer and on the Fedora build system. Might be worth investigating anyway, this is most likely a similar problem to https://github.com/balena/python-pqueue/issues/1\r\n\r\nShould i open a separate issue?",
    "performed_via_github_app": null
  },
  {
    "url": "https://api.github.com/repos/jupyter/notebook/issues/comments/391633490",
    "html_url": "https://github.com/jupyter/notebook/issues/3633#issuecomment-391633490",
    "issue_url": "https://api.github.com/repos/jupyter/notebook/issues/3633",
    "id": 391633490,
    "node_id": "MDEyOklzc3VlQ29tbWVudDM5MTYzMzQ5MA==",
    "user": {
      "login": "takluyver",
      "id": 327925,
      "node_id": "MDQ6VXNlcjMyNzkyNQ==",
      "avatar_url": "https://avatars.githubusercontent.com/u/327925?v=4",
      "gravatar_id": "",
      "url": "https://api.github.com/users/takluyver",
      "html_url": "https://github.com/takluyver",
      "followers_url": "https://api.github.com/users/takluyver/followers",
      "following_url": "https://api.github.com/users/takluyver/following{/other_user}",
      "gists_url": "https://api.github.com/users/takluyver/gists{/gist_id}",
      "starred_url": "https://api.github.com/users/takluyver/starred{/owner}{/repo}",
      "subscriptions_url": "https://api.github.com/users/takluyver/subscriptions",
      "organizations_url": "https://api.github.com/users/takluyver/orgs",
      "repos_url": "https://api.github.com/users/takluyver/repos",
      "events_url": "https://api.github.com/users/takluyver/events{/privacy}",
      "received_events_url": "https://api.github.com/users/takluyver/received_events",
      "type": "User",
      "site_admin": false
    },
    "created_at": "2018-05-24T08:30:48Z",
    "updated_at": "2018-05-24T08:30:48Z",
    "author_association": "MEMBER",
    "body": "That looks like it's an error moving a file to trash, which we do with the package [send2trash](https://pypi.python.org/pypi/send2trash).\r\n\r\nThe implementation is trying to find out:\r\n\r\n1. Is this file on the same device as $HOME?\r\n2. If not, what is the mount point of the device it's on?\r\n\r\nWe've seen some cases where these checks can go wrong when inside a container, but that looked a bit different. We added our own check to only trash files that are on the same device as home - this may be a good point to start debugging:\r\n\r\nhttps://github.com/jupyter/notebook/blob/5.5.0/notebook/services/contents/filemanager.py#L513-L518",
    "performed_via_github_app": null
  },
  {
    "url": "https://api.github.com/repos/jupyter/notebook/issues/comments/396067092",
    "html_url": "https://github.com/jupyter/notebook/issues/3633#issuecomment-396067092",
    "issue_url": "https://api.github.com/repos/jupyter/notebook/issues/3633",
    "id": 396067092,
    "node_id": "MDEyOklzc3VlQ29tbWVudDM5NjA2NzA5Mg==",
    "user": {
      "login": "takluyver",
      "id": 327925,
      "node_id": "MDQ6VXNlcjMyNzkyNQ==",
      "avatar_url": "https://avatars.githubusercontent.com/u/327925?v=4",
      "gravatar_id": "",
      "url": "https://api.github.com/users/takluyver",
      "html_url": "https://github.com/takluyver",
      "followers_url": "https://api.github.com/users/takluyver/followers",
      "following_url": "https://api.github.com/users/takluyver/following{/other_user}",
      "gists_url": "https://api.github.com/users/takluyver/gists{/gist_id}",
      "starred_url": "https://api.github.com/users/takluyver/starred{/owner}{/repo}",
      "subscriptions_url": "https://api.github.com/users/takluyver/subscriptions",
      "organizations_url": "https://api.github.com/users/takluyver/orgs",
      "repos_url": "https://api.github.com/users/takluyver/repos",
      "events_url": "https://api.github.com/users/takluyver/events{/privacy}",
      "received_events_url": "https://api.github.com/users/takluyver/received_events",
      "type": "User",
      "site_admin": false
    },
    "created_at": "2018-06-10T17:36:45Z",
    "updated_at": "2018-06-10T17:36:45Z",
    "author_association": "MEMBER",
    "body": "Closing as the original issue was resolved - feel free to open another one if we still need to debug the trash problem.",
    "performed_via_github_app": null
  },
  {
    "url": "https://api.github.com/repos/jupyter/notebook/issues/comments/396069300",
    "html_url": "https://github.com/jupyter/notebook/issues/3633#issuecomment-396069300",
    "issue_url": "https://api.github.com/repos/jupyter/notebook/issues/3633",
    "id": 396069300,
    "node_id": "MDEyOklzc3VlQ29tbWVudDM5NjA2OTMwMA==",
    "user": {
      "login": "hroncok",
      "id": 2401856,
      "node_id": "MDQ6VXNlcjI0MDE4NTY=",
      "avatar_url": "https://avatars.githubusercontent.com/u/2401856?v=4",
      "gravatar_id": "",
      "url": "https://api.github.com/users/hroncok",
      "html_url": "https://github.com/hroncok",
      "followers_url": "https://api.github.com/users/hroncok/followers",
      "following_url": "https://api.github.com/users/hroncok/following{/other_user}",
      "gists_url": "https://api.github.com/users/hroncok/gists{/gist_id}",
      "starred_url": "https://api.github.com/users/hroncok/starred{/owner}{/repo}",
      "subscriptions_url": "https://api.github.com/users/hroncok/subscriptions",
      "organizations_url": "https://api.github.com/users/hroncok/orgs",
      "repos_url": "https://api.github.com/users/hroncok/repos",
      "events_url": "https://api.github.com/users/hroncok/events{/privacy}",
      "received_events_url": "https://api.github.com/users/hroncok/received_events",
      "type": "User",
      "site_admin": false
    },
    "created_at": "2018-06-10T18:09:03Z",
    "updated_at": "2018-06-10T18:09:03Z",
    "author_association": "CONTRIBUTOR",
    "body": "Thank you. If it ever hits me again, I'll investigate. ",
    "performed_via_github_app": null
  },
  {
    "url": "https://api.github.com/repos/jupyter/notebook/issues/comments/478326636",
    "html_url": "https://github.com/jupyter/notebook/issues/3633#issuecomment-478326636",
    "issue_url": "https://api.github.com/repos/jupyter/notebook/issues/3633",
    "id": 478326636,
    "node_id": "MDEyOklzc3VlQ29tbWVudDQ3ODMyNjYzNg==",
    "user": {
      "login": "hroncok",
      "id": 2401856,
      "node_id": "MDQ6VXNlcjI0MDE4NTY=",
      "avatar_url": "https://avatars.githubusercontent.com/u/2401856?v=4",
      "gravatar_id": "",
      "url": "https://api.github.com/users/hroncok",
      "html_url": "https://github.com/hroncok",
      "followers_url": "https://api.github.com/users/hroncok/followers",
      "following_url": "https://api.github.com/users/hroncok/following{/other_user}",
      "gists_url": "https://api.github.com/users/hroncok/gists{/gist_id}",
      "starred_url": "https://api.github.com/users/hroncok/starred{/owner}{/repo}",
      "subscriptions_url": "https://api.github.com/users/hroncok/subscriptions",
      "organizations_url": "https://api.github.com/users/hroncok/orgs",
      "repos_url": "https://api.github.com/users/hroncok/repos",
      "events_url": "https://api.github.com/users/hroncok/events{/privacy}",
      "received_events_url": "https://api.github.com/users/hroncok/received_events",
      "type": "User",
      "site_admin": false
    },
    "created_at": "2019-03-31T09:40:10Z",
    "updated_at": "2019-03-31T09:40:10Z",
    "author_association": "CONTRIBUTOR",
    "body": "The trash failures: https://github.com/jupyter/notebook/issues/3130",
    "performed_via_github_app": null
  }
]
