[
  {
    "url": "https://api.github.com/repos/jupyter/notebook/issues/comments/660114255",
    "html_url": "https://github.com/jupyter/notebook/issues/5435#issuecomment-660114255",
    "issue_url": "https://api.github.com/repos/jupyter/notebook/issues/5435",
    "id": 660114255,
    "node_id": "MDEyOklzc3VlQ29tbWVudDY2MDExNDI1NQ==",
    "user": {
      "login": "tchaye59",
      "id": 18069576,
      "node_id": "MDQ6VXNlcjE4MDY5NTc2",
      "avatar_url": "https://avatars.githubusercontent.com/u/18069576?v=4",
      "gravatar_id": "",
      "url": "https://api.github.com/users/tchaye59",
      "html_url": "https://github.com/tchaye59",
      "followers_url": "https://api.github.com/users/tchaye59/followers",
      "following_url": "https://api.github.com/users/tchaye59/following{/other_user}",
      "gists_url": "https://api.github.com/users/tchaye59/gists{/gist_id}",
      "starred_url": "https://api.github.com/users/tchaye59/starred{/owner}{/repo}",
      "subscriptions_url": "https://api.github.com/users/tchaye59/subscriptions",
      "organizations_url": "https://api.github.com/users/tchaye59/orgs",
      "repos_url": "https://api.github.com/users/tchaye59/repos",
      "events_url": "https://api.github.com/users/tchaye59/events{/privacy}",
      "received_events_url": "https://api.github.com/users/tchaye59/received_events",
      "type": "User",
      "site_admin": false
    },
    "created_at": "2020-07-17T13:42:32Z",
    "updated_at": "2020-07-17T13:42:32Z",
    "author_association": "NONE",
    "body": "Hi! I have the same problem, did you find a solution?",
    "performed_via_github_app": null
  },
  {
    "url": "https://api.github.com/repos/jupyter/notebook/issues/comments/660116457",
    "html_url": "https://github.com/jupyter/notebook/issues/5435#issuecomment-660116457",
    "issue_url": "https://api.github.com/repos/jupyter/notebook/issues/5435",
    "id": 660116457,
    "node_id": "MDEyOklzc3VlQ29tbWVudDY2MDExNjQ1Nw==",
    "user": {
      "login": "mik-niborrr",
      "id": 63914683,
      "node_id": "MDQ6VXNlcjYzOTE0Njgz",
      "avatar_url": "https://avatars.githubusercontent.com/u/63914683?v=4",
      "gravatar_id": "",
      "url": "https://api.github.com/users/mik-niborrr",
      "html_url": "https://github.com/mik-niborrr",
      "followers_url": "https://api.github.com/users/mik-niborrr/followers",
      "following_url": "https://api.github.com/users/mik-niborrr/following{/other_user}",
      "gists_url": "https://api.github.com/users/mik-niborrr/gists{/gist_id}",
      "starred_url": "https://api.github.com/users/mik-niborrr/starred{/owner}{/repo}",
      "subscriptions_url": "https://api.github.com/users/mik-niborrr/subscriptions",
      "organizations_url": "https://api.github.com/users/mik-niborrr/orgs",
      "repos_url": "https://api.github.com/users/mik-niborrr/repos",
      "events_url": "https://api.github.com/users/mik-niborrr/events{/privacy}",
      "received_events_url": "https://api.github.com/users/mik-niborrr/received_events",
      "type": "User",
      "site_admin": false
    },
    "created_at": "2020-07-17T13:47:13Z",
    "updated_at": "2020-07-17T13:48:03Z",
    "author_association": "NONE",
    "body": "> Hi! I have the same problem, did you find a solution?\r\n\r\nHi, yes fortunately Jupyter went up and running once I set IP and port as follows:\r\njupyter notebook --ip=127.0.0.X --port=9999\r\n\r\nThough I am not quite sure if it will work the same with others",
    "performed_via_github_app": null
  },
  {
    "url": "https://api.github.com/repos/jupyter/notebook/issues/comments/660394836",
    "html_url": "https://github.com/jupyter/notebook/issues/5435#issuecomment-660394836",
    "issue_url": "https://api.github.com/repos/jupyter/notebook/issues/5435",
    "id": 660394836,
    "node_id": "MDEyOklzc3VlQ29tbWVudDY2MDM5NDgzNg==",
    "user": {
      "login": "tchaye59",
      "id": 18069576,
      "node_id": "MDQ6VXNlcjE4MDY5NTc2",
      "avatar_url": "https://avatars.githubusercontent.com/u/18069576?v=4",
      "gravatar_id": "",
      "url": "https://api.github.com/users/tchaye59",
      "html_url": "https://github.com/tchaye59",
      "followers_url": "https://api.github.com/users/tchaye59/followers",
      "following_url": "https://api.github.com/users/tchaye59/following{/other_user}",
      "gists_url": "https://api.github.com/users/tchaye59/gists{/gist_id}",
      "starred_url": "https://api.github.com/users/tchaye59/starred{/owner}{/repo}",
      "subscriptions_url": "https://api.github.com/users/tchaye59/subscriptions",
      "organizations_url": "https://api.github.com/users/tchaye59/orgs",
      "repos_url": "https://api.github.com/users/tchaye59/repos",
      "events_url": "https://api.github.com/users/tchaye59/events{/privacy}",
      "received_events_url": "https://api.github.com/users/tchaye59/received_events",
      "type": "User",
      "site_admin": false
    },
    "created_at": "2020-07-18T00:42:47Z",
    "updated_at": "2020-07-18T00:42:47Z",
    "author_association": "NONE",
    "body": "> > Hi! I have the same problem, did you find a solution?\r\n> \r\n> Hi, yes fortunately Jupyter went up and running once I set IP and port as follows:\r\n> jupyter notebook --ip=127.0.0.X --port=9999\r\n> \r\n> Though I am not quite sure if it will work the same with others\r\n\r\nThanks, it is working for me.\r\nI just change the default IP in the config file: **~/.jupyter/jupyter_notebook_config.py**\r\nTo generate this config file you have to run the command:  **jupyter notebook --generate-config**\r\nAfter you need to uncomment and set :   **c.NotebookApp.ip = '127.0.0.1'**",
    "performed_via_github_app": null
  },
  {
    "url": "https://api.github.com/repos/jupyter/notebook/issues/comments/660395153",
    "html_url": "https://github.com/jupyter/notebook/issues/5435#issuecomment-660395153",
    "issue_url": "https://api.github.com/repos/jupyter/notebook/issues/5435",
    "id": 660395153,
    "node_id": "MDEyOklzc3VlQ29tbWVudDY2MDM5NTE1Mw==",
    "user": {
      "login": "kevin-bates",
      "id": 22599560,
      "node_id": "MDQ6VXNlcjIyNTk5NTYw",
      "avatar_url": "https://avatars.githubusercontent.com/u/22599560?v=4",
      "gravatar_id": "",
      "url": "https://api.github.com/users/kevin-bates",
      "html_url": "https://github.com/kevin-bates",
      "followers_url": "https://api.github.com/users/kevin-bates/followers",
      "following_url": "https://api.github.com/users/kevin-bates/following{/other_user}",
      "gists_url": "https://api.github.com/users/kevin-bates/gists{/gist_id}",
      "starred_url": "https://api.github.com/users/kevin-bates/starred{/owner}{/repo}",
      "subscriptions_url": "https://api.github.com/users/kevin-bates/subscriptions",
      "organizations_url": "https://api.github.com/users/kevin-bates/orgs",
      "repos_url": "https://api.github.com/users/kevin-bates/repos",
      "events_url": "https://api.github.com/users/kevin-bates/events{/privacy}",
      "received_events_url": "https://api.github.com/users/kevin-bates/received_events",
      "type": "User",
      "site_admin": false
    },
    "created_at": "2020-07-18T00:44:51Z",
    "updated_at": "2020-07-18T00:44:51Z",
    "author_association": "MEMBER",
    "body": "Great responses - thank you.  Closing this issue.",
    "performed_via_github_app": null
  },
  {
    "url": "https://api.github.com/repos/jupyter/notebook/issues/comments/711573230",
    "html_url": "https://github.com/jupyter/notebook/issues/5435#issuecomment-711573230",
    "issue_url": "https://api.github.com/repos/jupyter/notebook/issues/5435",
    "id": 711573230,
    "node_id": "MDEyOklzc3VlQ29tbWVudDcxMTU3MzIzMA==",
    "user": {
      "login": "LIUxDD",
      "id": 58817676,
      "node_id": "MDQ6VXNlcjU4ODE3Njc2",
      "avatar_url": "https://avatars.githubusercontent.com/u/58817676?v=4",
      "gravatar_id": "",
      "url": "https://api.github.com/users/LIUxDD",
      "html_url": "https://github.com/LIUxDD",
      "followers_url": "https://api.github.com/users/LIUxDD/followers",
      "following_url": "https://api.github.com/users/LIUxDD/following{/other_user}",
      "gists_url": "https://api.github.com/users/LIUxDD/gists{/gist_id}",
      "starred_url": "https://api.github.com/users/LIUxDD/starred{/owner}{/repo}",
      "subscriptions_url": "https://api.github.com/users/LIUxDD/subscriptions",
      "organizations_url": "https://api.github.com/users/LIUxDD/orgs",
      "repos_url": "https://api.github.com/users/LIUxDD/repos",
      "events_url": "https://api.github.com/users/LIUxDD/events{/privacy}",
      "received_events_url": "https://api.github.com/users/LIUxDD/received_events",
      "type": "User",
      "site_admin": false
    },
    "created_at": "2020-10-19T05:05:03Z",
    "updated_at": "2020-10-19T05:05:03Z",
    "author_association": "NONE",
    "body": "> > > 嗨！我有同样的问题，您找到解决方案了吗？\r\n> > \r\n> > \r\n> > 嗨，是的，幸运的是，一旦我按如下所示设置IP和端口，Jupyter就可以启动并运行：\r\n> > jupyter notebook --ip = 127.0.0.X --port = 9999\r\n> > 虽然我不太确定它是否可以和其他人一起使用\r\n> \r\n> 谢谢，它为我工作。\r\n> 我只是更改了配置文件中的默认IP：**〜/ .jupyter / jupyter_notebook_config.py**\r\n> 要生成此配置文件，您必须运行以下命令： **jupyter notebook --generate-config**\r\n> 需要取消注释并设置后： **c.NotebookApp。 ip ='127.0.0.1'**\r\n\r\nThank you very much.",
    "performed_via_github_app": null
  }
]
