[
  {
    "url": "https://api.github.com/repos/jupyter/notebook/issues/comments/427776553",
    "html_url": "https://github.com/jupyter/notebook/issues/4067#issuecomment-427776553",
    "issue_url": "https://api.github.com/repos/jupyter/notebook/issues/4067",
    "id": 427776553,
    "node_id": "MDEyOklzc3VlQ29tbWVudDQyNzc3NjU1Mw==",
    "user": {
      "login": "ayorgo",
      "id": 3997638,
      "node_id": "MDQ6VXNlcjM5OTc2Mzg=",
      "avatar_url": "https://avatars.githubusercontent.com/u/3997638?v=4",
      "gravatar_id": "",
      "url": "https://api.github.com/users/ayorgo",
      "html_url": "https://github.com/ayorgo",
      "followers_url": "https://api.github.com/users/ayorgo/followers",
      "following_url": "https://api.github.com/users/ayorgo/following{/other_user}",
      "gists_url": "https://api.github.com/users/ayorgo/gists{/gist_id}",
      "starred_url": "https://api.github.com/users/ayorgo/starred{/owner}{/repo}",
      "subscriptions_url": "https://api.github.com/users/ayorgo/subscriptions",
      "organizations_url": "https://api.github.com/users/ayorgo/orgs",
      "repos_url": "https://api.github.com/users/ayorgo/repos",
      "events_url": "https://api.github.com/users/ayorgo/events{/privacy}",
      "received_events_url": "https://api.github.com/users/ayorgo/received_events",
      "type": "User",
      "site_admin": false
    },
    "created_at": "2018-10-08T09:48:23Z",
    "updated_at": "2018-10-08T17:35:20Z",
    "author_association": "NONE",
    "body": "Same issue on \"Run All Above\"/\"Run All Below\" in different notebooks of mine. Appears to be breaking the sequence randomly on each run of the same set of cells within the same notebook. Kernel restart/shutdown doesn't help.\r\n```\r\n$ jupyter --version\r\n4.4.0\r\n$ jupyter notebook --version\r\n5.7.0\r\n$ python --version\r\nPython 3.6.6\r\n$ conda --version\r\nconda 4.5.11\r\n$ ipython --version\r\n7.0.1\r\n```",
    "performed_via_github_app": null
  },
  {
    "url": "https://api.github.com/repos/jupyter/notebook/issues/comments/427881657",
    "html_url": "https://github.com/jupyter/notebook/issues/4067#issuecomment-427881657",
    "issue_url": "https://api.github.com/repos/jupyter/notebook/issues/4067",
    "id": 427881657,
    "node_id": "MDEyOklzc3VlQ29tbWVudDQyNzg4MTY1Nw==",
    "user": {
      "login": "cibic89",
      "id": 22660599,
      "node_id": "MDQ6VXNlcjIyNjYwNTk5",
      "avatar_url": "https://avatars.githubusercontent.com/u/22660599?v=4",
      "gravatar_id": "",
      "url": "https://api.github.com/users/cibic89",
      "html_url": "https://github.com/cibic89",
      "followers_url": "https://api.github.com/users/cibic89/followers",
      "following_url": "https://api.github.com/users/cibic89/following{/other_user}",
      "gists_url": "https://api.github.com/users/cibic89/gists{/gist_id}",
      "starred_url": "https://api.github.com/users/cibic89/starred{/owner}{/repo}",
      "subscriptions_url": "https://api.github.com/users/cibic89/subscriptions",
      "organizations_url": "https://api.github.com/users/cibic89/orgs",
      "repos_url": "https://api.github.com/users/cibic89/repos",
      "events_url": "https://api.github.com/users/cibic89/events{/privacy}",
      "received_events_url": "https://api.github.com/users/cibic89/received_events",
      "type": "User",
      "site_admin": false
    },
    "created_at": "2018-10-08T15:38:04Z",
    "updated_at": "2018-10-08T15:38:04Z",
    "author_association": "NONE",
    "body": "Having the same problem when running selected cells using shift on the keyboard...",
    "performed_via_github_app": null
  },
  {
    "url": "https://api.github.com/repos/jupyter/notebook/issues/comments/427927705",
    "html_url": "https://github.com/jupyter/notebook/issues/4067#issuecomment-427927705",
    "issue_url": "https://api.github.com/repos/jupyter/notebook/issues/4067",
    "id": 427927705,
    "node_id": "MDEyOklzc3VlQ29tbWVudDQyNzkyNzcwNQ==",
    "user": {
      "login": "ayorgo",
      "id": 3997638,
      "node_id": "MDQ6VXNlcjM5OTc2Mzg=",
      "avatar_url": "https://avatars.githubusercontent.com/u/3997638?v=4",
      "gravatar_id": "",
      "url": "https://api.github.com/users/ayorgo",
      "html_url": "https://github.com/ayorgo",
      "followers_url": "https://api.github.com/users/ayorgo/followers",
      "following_url": "https://api.github.com/users/ayorgo/following{/other_user}",
      "gists_url": "https://api.github.com/users/ayorgo/gists{/gist_id}",
      "starred_url": "https://api.github.com/users/ayorgo/starred{/owner}{/repo}",
      "subscriptions_url": "https://api.github.com/users/ayorgo/subscriptions",
      "organizations_url": "https://api.github.com/users/ayorgo/orgs",
      "repos_url": "https://api.github.com/users/ayorgo/repos",
      "events_url": "https://api.github.com/users/ayorgo/events{/privacy}",
      "received_events_url": "https://api.github.com/users/ayorgo/received_events",
      "type": "User",
      "site_admin": false
    },
    "created_at": "2018-10-08T18:05:48Z",
    "updated_at": "2018-10-08T18:05:48Z",
    "author_association": "NONE",
    "body": "Seems to have been addressed already: https://github.com/jupyter/notebook/issues/4052, https://github.com/ipython/ipython/issues/11348\r\nAlleged fix: https://github.com/ipython/ipykernel/pull/362",
    "performed_via_github_app": null
  },
  {
    "url": "https://api.github.com/repos/jupyter/notebook/issues/comments/428113167",
    "html_url": "https://github.com/jupyter/notebook/issues/4067#issuecomment-428113167",
    "issue_url": "https://api.github.com/repos/jupyter/notebook/issues/4067",
    "id": 428113167,
    "node_id": "MDEyOklzc3VlQ29tbWVudDQyODExMzE2Nw==",
    "user": {
      "login": "minrk",
      "id": 151929,
      "node_id": "MDQ6VXNlcjE1MTkyOQ==",
      "avatar_url": "https://avatars.githubusercontent.com/u/151929?v=4",
      "gravatar_id": "",
      "url": "https://api.github.com/users/minrk",
      "html_url": "https://github.com/minrk",
      "followers_url": "https://api.github.com/users/minrk/followers",
      "following_url": "https://api.github.com/users/minrk/following{/other_user}",
      "gists_url": "https://api.github.com/users/minrk/gists{/gist_id}",
      "starred_url": "https://api.github.com/users/minrk/starred{/owner}{/repo}",
      "subscriptions_url": "https://api.github.com/users/minrk/subscriptions",
      "organizations_url": "https://api.github.com/users/minrk/orgs",
      "repos_url": "https://api.github.com/users/minrk/repos",
      "events_url": "https://api.github.com/users/minrk/events{/privacy}",
      "received_events_url": "https://api.github.com/users/minrk/received_events",
      "type": "User",
      "site_admin": false
    },
    "created_at": "2018-10-09T08:51:28Z",
    "updated_at": "2018-10-09T08:51:28Z",
    "author_association": "MEMBER",
    "body": "Closing as duplicate. ipykernel 5.1 should be out with the fix shortly.",
    "performed_via_github_app": null
  }
]
