[
  {
    "url": "https://api.github.com/repos/jupyter/notebook/issues/comments/282305578",
    "html_url": "https://github.com/jupyter/notebook/issues/2221#issuecomment-282305578",
    "issue_url": "https://api.github.com/repos/jupyter/notebook/issues/2221",
    "id": 282305578,
    "node_id": "MDEyOklzc3VlQ29tbWVudDI4MjMwNTU3OA==",
    "user": {
      "login": "takluyver",
      "id": 327925,
      "node_id": "MDQ6VXNlcjMyNzkyNQ==",
      "avatar_url": "https://avatars.githubusercontent.com/u/327925?v=4",
      "gravatar_id": "",
      "url": "https://api.github.com/users/takluyver",
      "html_url": "https://github.com/takluyver",
      "followers_url": "https://api.github.com/users/takluyver/followers",
      "following_url": "https://api.github.com/users/takluyver/following{/other_user}",
      "gists_url": "https://api.github.com/users/takluyver/gists{/gist_id}",
      "starred_url": "https://api.github.com/users/takluyver/starred{/owner}{/repo}",
      "subscriptions_url": "https://api.github.com/users/takluyver/subscriptions",
      "organizations_url": "https://api.github.com/users/takluyver/orgs",
      "repos_url": "https://api.github.com/users/takluyver/repos",
      "events_url": "https://api.github.com/users/takluyver/events{/privacy}",
      "received_events_url": "https://api.github.com/users/takluyver/received_events",
      "type": "User",
      "site_admin": false
    },
    "created_at": "2017-02-24T14:34:35Z",
    "updated_at": "2017-02-24T14:34:35Z",
    "author_association": "MEMBER",
    "body": "That doesn't look familiar. Can you show the bottom of the traceback it gives?\r\n\r\n(Preferably copy and paste errors as text rather than screenshots - it's easier to read and it means people can search based on the error message. You can copy text in the command prompt from the right click menu)",
    "performed_via_github_app": null
  },
  {
    "url": "https://api.github.com/repos/jupyter/notebook/issues/comments/282312537",
    "html_url": "https://github.com/jupyter/notebook/issues/2221#issuecomment-282312537",
    "issue_url": "https://api.github.com/repos/jupyter/notebook/issues/2221",
    "id": 282312537,
    "node_id": "MDEyOklzc3VlQ29tbWVudDI4MjMxMjUzNw==",
    "user": {
      "login": "manansatra3",
      "id": 21975482,
      "node_id": "MDQ6VXNlcjIxOTc1NDgy",
      "avatar_url": "https://avatars.githubusercontent.com/u/21975482?v=4",
      "gravatar_id": "",
      "url": "https://api.github.com/users/manansatra3",
      "html_url": "https://github.com/manansatra3",
      "followers_url": "https://api.github.com/users/manansatra3/followers",
      "following_url": "https://api.github.com/users/manansatra3/following{/other_user}",
      "gists_url": "https://api.github.com/users/manansatra3/gists{/gist_id}",
      "starred_url": "https://api.github.com/users/manansatra3/starred{/owner}{/repo}",
      "subscriptions_url": "https://api.github.com/users/manansatra3/subscriptions",
      "organizations_url": "https://api.github.com/users/manansatra3/orgs",
      "repos_url": "https://api.github.com/users/manansatra3/repos",
      "events_url": "https://api.github.com/users/manansatra3/events{/privacy}",
      "received_events_url": "https://api.github.com/users/manansatra3/received_events",
      "type": "User",
      "site_admin": false
    },
    "created_at": "2017-02-24T15:01:30Z",
    "updated_at": "2017-02-24T15:01:30Z",
    "author_association": "NONE",
    "body": "hey @takluyver here's the error:\r\n\r\nC:\\Users\\MANAN>jupyter notebook\r\nTraceback (most recent call last):\r\n  File \"C:\\Users\\MANAN\\Anaconda3\\lib\\site-packages\\tornado\\platform\\common.py\", line 44, in __init__\r\n    self.writer.connect(connect_address)\r\nTimeoutError: [WinError 10060] A connection attempt failed because the connected party did not properly respond after a period of time, or established connection failed because connected host has failed to respond\r\n\r\nDuring handling of the above exception, another exception occurred:\r\n\r\nTraceback (most recent call last):\r\n  File \"C:\\Users\\MANAN\\Anaconda3\\Scripts\\jupyter-notebook-script.py\", line 5, in <module>\r\n    sys.exit(notebook.notebookapp.main())\r\n  File \"C:\\Users\\MANAN\\Anaconda3\\lib\\site-packages\\jupyter_core\\application.py\", line 267, in launch_instance\r\n    return super(JupyterApp, cls).launch_instance(argv=argv, **kwargs)\r\n  File \"C:\\Users\\MANAN\\Anaconda3\\lib\\site-packages\\traitlets\\config\\application.py\", line 657, in launch_instance\r\n    app.initialize(argv)\r\n  File \"<decorator-gen-7>\", line 2, in initialize\r\n  File \"C:\\Users\\MANAN\\Anaconda3\\lib\\site-packages\\traitlets\\config\\application.py\", line 87, in catch_config_error\r\n    return method(app, *args, **kwargs)\r\n  File \"C:\\Users\\MANAN\\Anaconda3\\lib\\site-packages\\notebook\\notebookapp.py\", line 1142, in initialize\r\n    self.init_webapp()\r\n  File \"C:\\Users\\MANAN\\Anaconda3\\lib\\site-packages\\notebook\\notebookapp.py\", line 983, in init_webapp\r\n    self.http_server.listen(port, self.ip)\r\n  File \"C:\\Users\\MANAN\\Anaconda3\\lib\\site-packages\\tornado\\tcpserver.py\", line 127, in listen\r\n    self.add_sockets(sockets)\r\n  File \"C:\\Users\\MANAN\\Anaconda3\\lib\\site-packages\\tornado\\tcpserver.py\", line 139, in add_sockets\r\n    self.io_loop = IOLoop.current()\r\n  File \"C:\\Users\\MANAN\\Anaconda3\\lib\\site-packages\\tornado\\ioloop.py\", line 213, in current\r\n    return IOLoop.instance()\r\n  File \"C:\\Users\\MANAN\\Anaconda3\\lib\\site-packages\\tornado\\ioloop.py\", line 161, in instance\r\n    IOLoop._instance = IOLoop()\r\n  File \"C:\\Users\\MANAN\\Anaconda3\\lib\\site-packages\\tornado\\util.py\", line 278, in __new__\r\n    instance.initialize(*args, **init_kwargs)\r\n  File \"C:\\Users\\MANAN\\Anaconda3\\lib\\site-packages\\zmq\\eventloop\\ioloop.py\", line 139, in initialize\r\n    super(ZMQIOLoop, self).initialize(impl=impl, **kwargs)\r\n  File \"C:\\Users\\MANAN\\Anaconda3\\lib\\site-packages\\tornado\\ioloop.py\", line 705, in initialize\r\n    self._waker = Waker()\r\n  File \"C:\\Users\\MANAN\\Anaconda3\\lib\\site-packages\\tornado\\platform\\common.py\", line 48, in __init__\r\n    detail[0] != errno.WSAEADDRINUSE):\r\nTypeError: 'TimeoutError' object is not subscriptable\r\n\r\nC:\\Users\\MANAN>",
    "performed_via_github_app": null
  },
  {
    "url": "https://api.github.com/repos/jupyter/notebook/issues/comments/282314205",
    "html_url": "https://github.com/jupyter/notebook/issues/2221#issuecomment-282314205",
    "issue_url": "https://api.github.com/repos/jupyter/notebook/issues/2221",
    "id": 282314205,
    "node_id": "MDEyOklzc3VlQ29tbWVudDI4MjMxNDIwNQ==",
    "user": {
      "login": "takluyver",
      "id": 327925,
      "node_id": "MDQ6VXNlcjMyNzkyNQ==",
      "avatar_url": "https://avatars.githubusercontent.com/u/327925?v=4",
      "gravatar_id": "",
      "url": "https://api.github.com/users/takluyver",
      "html_url": "https://github.com/takluyver",
      "followers_url": "https://api.github.com/users/takluyver/followers",
      "following_url": "https://api.github.com/users/takluyver/following{/other_user}",
      "gists_url": "https://api.github.com/users/takluyver/gists{/gist_id}",
      "starred_url": "https://api.github.com/users/takluyver/starred{/owner}{/repo}",
      "subscriptions_url": "https://api.github.com/users/takluyver/subscriptions",
      "organizations_url": "https://api.github.com/users/takluyver/orgs",
      "repos_url": "https://api.github.com/users/takluyver/repos",
      "events_url": "https://api.github.com/users/takluyver/events{/privacy}",
      "received_events_url": "https://api.github.com/users/takluyver/received_events",
      "type": "User",
      "site_admin": false
    },
    "created_at": "2017-02-24T15:08:34Z",
    "updated_at": "2017-02-24T15:08:34Z",
    "author_association": "MEMBER",
    "body": "It sounds a bit similar to #1936, though it's a slightly different error message. Is it possible there's some other security software on the machine, or that you couldn't fully disable the one you mentioned?",
    "performed_via_github_app": null
  },
  {
    "url": "https://api.github.com/repos/jupyter/notebook/issues/comments/282316781",
    "html_url": "https://github.com/jupyter/notebook/issues/2221#issuecomment-282316781",
    "issue_url": "https://api.github.com/repos/jupyter/notebook/issues/2221",
    "id": 282316781,
    "node_id": "MDEyOklzc3VlQ29tbWVudDI4MjMxNjc4MQ==",
    "user": {
      "login": "manansatra3",
      "id": 21975482,
      "node_id": "MDQ6VXNlcjIxOTc1NDgy",
      "avatar_url": "https://avatars.githubusercontent.com/u/21975482?v=4",
      "gravatar_id": "",
      "url": "https://api.github.com/users/manansatra3",
      "html_url": "https://github.com/manansatra3",
      "followers_url": "https://api.github.com/users/manansatra3/followers",
      "following_url": "https://api.github.com/users/manansatra3/following{/other_user}",
      "gists_url": "https://api.github.com/users/manansatra3/gists{/gist_id}",
      "starred_url": "https://api.github.com/users/manansatra3/starred{/owner}{/repo}",
      "subscriptions_url": "https://api.github.com/users/manansatra3/subscriptions",
      "organizations_url": "https://api.github.com/users/manansatra3/orgs",
      "repos_url": "https://api.github.com/users/manansatra3/repos",
      "events_url": "https://api.github.com/users/manansatra3/events{/privacy}",
      "received_events_url": "https://api.github.com/users/manansatra3/received_events",
      "type": "User",
      "site_admin": false
    },
    "created_at": "2017-02-24T15:18:23Z",
    "updated_at": "2017-02-24T15:18:44Z",
    "author_association": "NONE",
    "body": "@takluyver  Well it sounds similar to many such queries on stackoverflow as well but none of them are same as this unfortunately.\r\n\r\nYes, I have QuickHeal Antivirus installed in my system on top of the default windows firewall. I disabled both of them completely ( I am sure about this since I have installed many more applications by disabling the AV in similar fashion ).\r\nAlso, I installed virtual machine, loaded ubuntu, installed (with AV turned ON) anaconda and tried starting jupyter notebook. Surprisingly, it worked all fine on ubuntu.",
    "performed_via_github_app": null
  },
  {
    "url": "https://api.github.com/repos/jupyter/notebook/issues/comments/283044226",
    "html_url": "https://github.com/jupyter/notebook/issues/2221#issuecomment-283044226",
    "issue_url": "https://api.github.com/repos/jupyter/notebook/issues/2221",
    "id": 283044226,
    "node_id": "MDEyOklzc3VlQ29tbWVudDI4MzA0NDIyNg==",
    "user": {
      "login": "manansatra3",
      "id": 21975482,
      "node_id": "MDQ6VXNlcjIxOTc1NDgy",
      "avatar_url": "https://avatars.githubusercontent.com/u/21975482?v=4",
      "gravatar_id": "",
      "url": "https://api.github.com/users/manansatra3",
      "html_url": "https://github.com/manansatra3",
      "followers_url": "https://api.github.com/users/manansatra3/followers",
      "following_url": "https://api.github.com/users/manansatra3/following{/other_user}",
      "gists_url": "https://api.github.com/users/manansatra3/gists{/gist_id}",
      "starred_url": "https://api.github.com/users/manansatra3/starred{/owner}{/repo}",
      "subscriptions_url": "https://api.github.com/users/manansatra3/subscriptions",
      "organizations_url": "https://api.github.com/users/manansatra3/orgs",
      "repos_url": "https://api.github.com/users/manansatra3/repos",
      "events_url": "https://api.github.com/users/manansatra3/events{/privacy}",
      "received_events_url": "https://api.github.com/users/manansatra3/received_events",
      "type": "User",
      "site_admin": false
    },
    "created_at": "2017-02-28T13:52:27Z",
    "updated_at": "2017-02-28T13:52:27Z",
    "author_association": "NONE",
    "body": "The issue is solved. I instead of disabling my AV, uninstalled it and then it worked for me. After installation and first run of jupyter notebook, I reinstalled my AV and still worked fine. So, my issue is resolved. We can close this issue. Thank-you @takluyver for the help and support provided!",
    "performed_via_github_app": null
  },
  {
    "url": "https://api.github.com/repos/jupyter/notebook/issues/comments/361072948",
    "html_url": "https://github.com/jupyter/notebook/issues/2221#issuecomment-361072948",
    "issue_url": "https://api.github.com/repos/jupyter/notebook/issues/2221",
    "id": 361072948,
    "node_id": "MDEyOklzc3VlQ29tbWVudDM2MTA3Mjk0OA==",
    "user": {
      "login": "shaad1994",
      "id": 32477955,
      "node_id": "MDQ6VXNlcjMyNDc3OTU1",
      "avatar_url": "https://avatars.githubusercontent.com/u/32477955?v=4",
      "gravatar_id": "",
      "url": "https://api.github.com/users/shaad1994",
      "html_url": "https://github.com/shaad1994",
      "followers_url": "https://api.github.com/users/shaad1994/followers",
      "following_url": "https://api.github.com/users/shaad1994/following{/other_user}",
      "gists_url": "https://api.github.com/users/shaad1994/gists{/gist_id}",
      "starred_url": "https://api.github.com/users/shaad1994/starred{/owner}{/repo}",
      "subscriptions_url": "https://api.github.com/users/shaad1994/subscriptions",
      "organizations_url": "https://api.github.com/users/shaad1994/orgs",
      "repos_url": "https://api.github.com/users/shaad1994/repos",
      "events_url": "https://api.github.com/users/shaad1994/events{/privacy}",
      "received_events_url": "https://api.github.com/users/shaad1994/received_events",
      "type": "User",
      "site_admin": false
    },
    "created_at": "2018-01-28T15:54:34Z",
    "updated_at": "2018-01-28T15:54:34Z",
    "author_association": "NONE",
    "body": "i have a prblem .. pls someone help me to fix this... when i tried to open jupyter notebook this is happened ..\r\n\r\n\r\nMicrosoft Windows [Version 10.0.10240]\r\n(c) 2015 Microsoft Corporation. All rights reserved.\r\n\r\nC:\\Users\\Dell>jupyter notebook\r\nTraceback (most recent call last):\r\n  File \"C:\\Users\\Dell\\Anaconda2\\Scripts\\jupyter-notebook-script.py\", line 10, in <module>\r\n    sys.exit(main())\r\n  File \"C:\\Users\\Dell\\Anaconda2\\lib\\site-packages\\jupyter_core\\application.py\", line 267, in launch_instance\r\n    return super(JupyterApp, cls).launch_instance(argv=argv, **kwargs)\r\n  File \"C:\\Users\\Dell\\Anaconda2\\lib\\site-packages\\traitlets\\config\\application.py\", line 657, in launch_instance\r\n    app.initialize(argv)\r\n  File \"<decorator-gen-7>\", line 2, in initialize\r\n  File \"C:\\Users\\Dell\\Anaconda2\\lib\\site-packages\\traitlets\\config\\application.py\", line 87, in catch_config_error\r\n    return method(app, *args, **kwargs)\r\n  File \"C:\\Users\\Dell\\Anaconda2\\lib\\site-packages\\notebook\\notebookapp.py\", line 1296, in initialize\r\n    self.init_webapp()\r\n  File \"C:\\Users\\Dell\\Anaconda2\\lib\\site-packages\\notebook\\notebookapp.py\", line 1120, in init_webapp\r\n    self.http_server.listen(port, self.ip)\r\n  File \"C:\\Users\\Dell\\Anaconda2\\lib\\site-packages\\tornado\\tcpserver.py\", line 143, in listen\r\n    self.add_sockets(sockets)\r\n  File \"C:\\Users\\Dell\\Anaconda2\\lib\\site-packages\\tornado\\tcpserver.py\", line 155, in add_sockets\r\n    self.io_loop = IOLoop.current()\r\n  File \"C:\\Users\\Dell\\Anaconda2\\lib\\site-packages\\tornado\\ioloop.py\", line 214, in current\r\n    return IOLoop.instance()\r\n  File \"C:\\Users\\Dell\\Anaconda2\\lib\\site-packages\\tornado\\ioloop.py\", line 162, in instance\r\n    IOLoop._instance = IOLoop()\r\n  File \"C:\\Users\\Dell\\Anaconda2\\lib\\site-packages\\tornado\\util.py\", line 293, in __new__\r\n    instance.initialize(*args, **init_kwargs)\r\n  File \"C:\\Users\\Dell\\Anaconda2\\lib\\site-packages\\zmq\\eventloop\\ioloop.py\", line 139, in initialize\r\n    super(ZMQIOLoop, self).initialize(impl=impl, **kwargs)\r\n  File \"C:\\Users\\Dell\\Anaconda2\\lib\\site-packages\\tornado\\ioloop.py\", line 709, in initialize\r\n    self._waker = Waker()\r\n  File \"C:\\Users\\Dell\\Anaconda2\\lib\\site-packages\\tornado\\platform\\common.py\", line 64, in __init__\r\n    self.writer.connect(connect_address)\r\n  File \"C:\\Users\\Dell\\Anaconda2\\lib\\socket.py\", line 228, in meth\r\n    return getattr(self._sock,name)(*args)\r\nsocket.error: [Errno 10060] A connection attempt failed because the connected party did not properly respond after a period of time, or established connection failed because connected host has failed to respond\r\n\r\nC:\\Users\\Dell>",
    "performed_via_github_app": null
  },
  {
    "url": "https://api.github.com/repos/jupyter/notebook/issues/comments/361078859",
    "html_url": "https://github.com/jupyter/notebook/issues/2221#issuecomment-361078859",
    "issue_url": "https://api.github.com/repos/jupyter/notebook/issues/2221",
    "id": 361078859,
    "node_id": "MDEyOklzc3VlQ29tbWVudDM2MTA3ODg1OQ==",
    "user": {
      "login": "takluyver",
      "id": 327925,
      "node_id": "MDQ6VXNlcjMyNzkyNQ==",
      "avatar_url": "https://avatars.githubusercontent.com/u/327925?v=4",
      "gravatar_id": "",
      "url": "https://api.github.com/users/takluyver",
      "html_url": "https://github.com/takluyver",
      "followers_url": "https://api.github.com/users/takluyver/followers",
      "following_url": "https://api.github.com/users/takluyver/following{/other_user}",
      "gists_url": "https://api.github.com/users/takluyver/gists{/gist_id}",
      "starred_url": "https://api.github.com/users/takluyver/starred{/owner}{/repo}",
      "subscriptions_url": "https://api.github.com/users/takluyver/subscriptions",
      "organizations_url": "https://api.github.com/users/takluyver/orgs",
      "repos_url": "https://api.github.com/users/takluyver/repos",
      "events_url": "https://api.github.com/users/takluyver/events{/privacy}",
      "received_events_url": "https://api.github.com/users/takluyver/received_events",
      "type": "User",
      "site_admin": false
    },
    "created_at": "2018-01-28T17:15:11Z",
    "updated_at": "2018-01-28T17:15:11Z",
    "author_association": "MEMBER",
    "body": "Don't think I've seen that error before. Do you have any security software on your computer? Some security things seem to interfere with the connections we use.",
    "performed_via_github_app": null
  },
  {
    "url": "https://api.github.com/repos/jupyter/notebook/issues/comments/361893646",
    "html_url": "https://github.com/jupyter/notebook/issues/2221#issuecomment-361893646",
    "issue_url": "https://api.github.com/repos/jupyter/notebook/issues/2221",
    "id": 361893646,
    "node_id": "MDEyOklzc3VlQ29tbWVudDM2MTg5MzY0Ng==",
    "user": {
      "login": "raedbsili1991",
      "id": 31764213,
      "node_id": "MDQ6VXNlcjMxNzY0MjEz",
      "avatar_url": "https://avatars.githubusercontent.com/u/31764213?v=4",
      "gravatar_id": "",
      "url": "https://api.github.com/users/raedbsili1991",
      "html_url": "https://github.com/raedbsili1991",
      "followers_url": "https://api.github.com/users/raedbsili1991/followers",
      "following_url": "https://api.github.com/users/raedbsili1991/following{/other_user}",
      "gists_url": "https://api.github.com/users/raedbsili1991/gists{/gist_id}",
      "starred_url": "https://api.github.com/users/raedbsili1991/starred{/owner}{/repo}",
      "subscriptions_url": "https://api.github.com/users/raedbsili1991/subscriptions",
      "organizations_url": "https://api.github.com/users/raedbsili1991/orgs",
      "repos_url": "https://api.github.com/users/raedbsili1991/repos",
      "events_url": "https://api.github.com/users/raedbsili1991/events{/privacy}",
      "received_events_url": "https://api.github.com/users/raedbsili1991/received_events",
      "type": "User",
      "site_admin": false
    },
    "created_at": "2018-01-31T10:42:26Z",
    "updated_at": "2018-01-31T10:42:26Z",
    "author_association": "NONE",
    "body": "Hi, \r\n\r\nI am receiving the same error when running Jupyter Notebook, although my firewall is completely deactivated! It was just working fine by yesterday! \r\nToday, it shows this error! ",
    "performed_via_github_app": null
  },
  {
    "url": "https://api.github.com/repos/jupyter/notebook/issues/comments/361894641",
    "html_url": "https://github.com/jupyter/notebook/issues/2221#issuecomment-361894641",
    "issue_url": "https://api.github.com/repos/jupyter/notebook/issues/2221",
    "id": 361894641,
    "node_id": "MDEyOklzc3VlQ29tbWVudDM2MTg5NDY0MQ==",
    "user": {
      "login": "shaad1994",
      "id": 32477955,
      "node_id": "MDQ6VXNlcjMyNDc3OTU1",
      "avatar_url": "https://avatars.githubusercontent.com/u/32477955?v=4",
      "gravatar_id": "",
      "url": "https://api.github.com/users/shaad1994",
      "html_url": "https://github.com/shaad1994",
      "followers_url": "https://api.github.com/users/shaad1994/followers",
      "following_url": "https://api.github.com/users/shaad1994/following{/other_user}",
      "gists_url": "https://api.github.com/users/shaad1994/gists{/gist_id}",
      "starred_url": "https://api.github.com/users/shaad1994/starred{/owner}{/repo}",
      "subscriptions_url": "https://api.github.com/users/shaad1994/subscriptions",
      "organizations_url": "https://api.github.com/users/shaad1994/orgs",
      "repos_url": "https://api.github.com/users/shaad1994/repos",
      "events_url": "https://api.github.com/users/shaad1994/events{/privacy}",
      "received_events_url": "https://api.github.com/users/shaad1994/received_events",
      "type": "User",
      "site_admin": false
    },
    "created_at": "2018-01-31T10:45:59Z",
    "updated_at": "2018-01-31T10:45:59Z",
    "author_association": "NONE",
    "body": "how i deactivated windows firewall???",
    "performed_via_github_app": null
  }
]
