[
  {
    "url": "https://api.github.com/repos/jupyter/notebook/issues/comments/294886847",
    "html_url": "https://github.com/jupyter/notebook/issues/2416#issuecomment-294886847",
    "issue_url": "https://api.github.com/repos/jupyter/notebook/issues/2416",
    "id": 294886847,
    "node_id": "MDEyOklzc3VlQ29tbWVudDI5NDg4Njg0Nw==",
    "user": {
      "login": "takluyver",
      "id": 327925,
      "node_id": "MDQ6VXNlcjMyNzkyNQ==",
      "avatar_url": "https://avatars.githubusercontent.com/u/327925?v=4",
      "gravatar_id": "",
      "url": "https://api.github.com/users/takluyver",
      "html_url": "https://github.com/takluyver",
      "followers_url": "https://api.github.com/users/takluyver/followers",
      "following_url": "https://api.github.com/users/takluyver/following{/other_user}",
      "gists_url": "https://api.github.com/users/takluyver/gists{/gist_id}",
      "starred_url": "https://api.github.com/users/takluyver/starred{/owner}{/repo}",
      "subscriptions_url": "https://api.github.com/users/takluyver/subscriptions",
      "organizations_url": "https://api.github.com/users/takluyver/orgs",
      "repos_url": "https://api.github.com/users/takluyver/repos",
      "events_url": "https://api.github.com/users/takluyver/events{/privacy}",
      "received_events_url": "https://api.github.com/users/takluyver/received_events",
      "type": "User",
      "site_admin": false
    },
    "created_at": "2017-04-18T15:44:40Z",
    "updated_at": "2017-04-18T15:44:40Z",
    "author_association": "MEMBER",
    "body": "That sounds like a file that should be JSON is not valid JSON - maybe it's been left over as an empty file. We should probably handle that with a nicer error message.",
    "performed_via_github_app": null
  },
  {
    "url": "https://api.github.com/repos/jupyter/notebook/issues/comments/452510820",
    "html_url": "https://github.com/jupyter/notebook/issues/2416#issuecomment-452510820",
    "issue_url": "https://api.github.com/repos/jupyter/notebook/issues/2416",
    "id": 452510820,
    "node_id": "MDEyOklzc3VlQ29tbWVudDQ1MjUxMDgyMA==",
    "user": {
      "login": "sina-masoud-ansari",
      "id": 830419,
      "node_id": "MDQ6VXNlcjgzMDQxOQ==",
      "avatar_url": "https://avatars.githubusercontent.com/u/830419?v=4",
      "gravatar_id": "",
      "url": "https://api.github.com/users/sina-masoud-ansari",
      "html_url": "https://github.com/sina-masoud-ansari",
      "followers_url": "https://api.github.com/users/sina-masoud-ansari/followers",
      "following_url": "https://api.github.com/users/sina-masoud-ansari/following{/other_user}",
      "gists_url": "https://api.github.com/users/sina-masoud-ansari/gists{/gist_id}",
      "starred_url": "https://api.github.com/users/sina-masoud-ansari/starred{/owner}{/repo}",
      "subscriptions_url": "https://api.github.com/users/sina-masoud-ansari/subscriptions",
      "organizations_url": "https://api.github.com/users/sina-masoud-ansari/orgs",
      "repos_url": "https://api.github.com/users/sina-masoud-ansari/repos",
      "events_url": "https://api.github.com/users/sina-masoud-ansari/events{/privacy}",
      "received_events_url": "https://api.github.com/users/sina-masoud-ansari/received_events",
      "type": "User",
      "site_admin": false
    },
    "created_at": "2019-01-09T00:15:44Z",
    "updated_at": "2019-01-09T00:15:44Z",
    "author_association": "NONE",
    "body": "This is because it was finding .html files as well. I believe this is fixed in the latest commit ( #4137 ) in notebook\\notebookapp.py line 1842 which specifies json files only",
    "performed_via_github_app": null
  },
  {
    "url": "https://api.github.com/repos/jupyter/notebook/issues/comments/454168535",
    "html_url": "https://github.com/jupyter/notebook/issues/2416#issuecomment-454168535",
    "issue_url": "https://api.github.com/repos/jupyter/notebook/issues/2416",
    "id": 454168535,
    "node_id": "MDEyOklzc3VlQ29tbWVudDQ1NDE2ODUzNQ==",
    "user": {
      "login": "aknrdureegaesr",
      "id": 1033352,
      "node_id": "MDQ6VXNlcjEwMzMzNTI=",
      "avatar_url": "https://avatars.githubusercontent.com/u/1033352?v=4",
      "gravatar_id": "",
      "url": "https://api.github.com/users/aknrdureegaesr",
      "html_url": "https://github.com/aknrdureegaesr",
      "followers_url": "https://api.github.com/users/aknrdureegaesr/followers",
      "following_url": "https://api.github.com/users/aknrdureegaesr/following{/other_user}",
      "gists_url": "https://api.github.com/users/aknrdureegaesr/gists{/gist_id}",
      "starred_url": "https://api.github.com/users/aknrdureegaesr/starred{/owner}{/repo}",
      "subscriptions_url": "https://api.github.com/users/aknrdureegaesr/subscriptions",
      "organizations_url": "https://api.github.com/users/aknrdureegaesr/orgs",
      "repos_url": "https://api.github.com/users/aknrdureegaesr/repos",
      "events_url": "https://api.github.com/users/aknrdureegaesr/events{/privacy}",
      "received_events_url": "https://api.github.com/users/aknrdureegaesr/received_events",
      "type": "User",
      "site_admin": false
    },
    "created_at": "2019-01-14T21:29:44Z",
    "updated_at": "2019-01-14T21:29:44Z",
    "author_association": "NONE",
    "body": "> This is because it was finding .html files as well. I believe this is fixed in the latest commit (??? ) in notebook\\notebookapp.py line 1842 which specifies json files only\r\n\r\nI think you mean commit adcb7025ca. (FWIW: Commits can be referenced in GitHub comments without a leading hashmark.) By using the hashmark the way you do, you are referencing the issue with that number. That issue I consider unrelated.",
    "performed_via_github_app": null
  },
  {
    "url": "https://api.github.com/repos/jupyter/notebook/issues/comments/480040962",
    "html_url": "https://github.com/jupyter/notebook/issues/2416#issuecomment-480040962",
    "issue_url": "https://api.github.com/repos/jupyter/notebook/issues/2416",
    "id": 480040962,
    "node_id": "MDEyOklzc3VlQ29tbWVudDQ4MDA0MDk2Mg==",
    "user": {
      "login": "arvoelke",
      "id": 5420057,
      "node_id": "MDQ6VXNlcjU0MjAwNTc=",
      "avatar_url": "https://avatars.githubusercontent.com/u/5420057?v=4",
      "gravatar_id": "",
      "url": "https://api.github.com/users/arvoelke",
      "html_url": "https://github.com/arvoelke",
      "followers_url": "https://api.github.com/users/arvoelke/followers",
      "following_url": "https://api.github.com/users/arvoelke/following{/other_user}",
      "gists_url": "https://api.github.com/users/arvoelke/gists{/gist_id}",
      "starred_url": "https://api.github.com/users/arvoelke/starred{/owner}{/repo}",
      "subscriptions_url": "https://api.github.com/users/arvoelke/subscriptions",
      "organizations_url": "https://api.github.com/users/arvoelke/orgs",
      "repos_url": "https://api.github.com/users/arvoelke/repos",
      "events_url": "https://api.github.com/users/arvoelke/events{/privacy}",
      "received_events_url": "https://api.github.com/users/arvoelke/received_events",
      "type": "User",
      "site_admin": false
    },
    "created_at": "2019-04-04T19:56:54Z",
    "updated_at": "2019-04-04T19:56:54Z",
    "author_association": "NONE",
    "body": "I have the same issue, but with a slightly different error message:\r\n```\r\njson.decoder.JSONDecodeError: Expecting value: line 2 column 1 (char 1)\r\n```\r\nBut I cannot find the location of my config file. There are directories `~/miniconda3/envs/loihi/etc/jupyter/nbconfig/` and `~/.jupyter/` but it's not in there.\r\n\r\nI can start servers, but I get this message if I try to `stop` or `list` them.",
    "performed_via_github_app": null
  },
  {
    "url": "https://api.github.com/repos/jupyter/notebook/issues/comments/480042617",
    "html_url": "https://github.com/jupyter/notebook/issues/2416#issuecomment-480042617",
    "issue_url": "https://api.github.com/repos/jupyter/notebook/issues/2416",
    "id": 480042617,
    "node_id": "MDEyOklzc3VlQ29tbWVudDQ4MDA0MjYxNw==",
    "user": {
      "login": "arvoelke",
      "id": 5420057,
      "node_id": "MDQ6VXNlcjU0MjAwNTc=",
      "avatar_url": "https://avatars.githubusercontent.com/u/5420057?v=4",
      "gravatar_id": "",
      "url": "https://api.github.com/users/arvoelke",
      "html_url": "https://github.com/arvoelke",
      "followers_url": "https://api.github.com/users/arvoelke/followers",
      "following_url": "https://api.github.com/users/arvoelke/following{/other_user}",
      "gists_url": "https://api.github.com/users/arvoelke/gists{/gist_id}",
      "starred_url": "https://api.github.com/users/arvoelke/starred{/owner}{/repo}",
      "subscriptions_url": "https://api.github.com/users/arvoelke/subscriptions",
      "organizations_url": "https://api.github.com/users/arvoelke/orgs",
      "repos_url": "https://api.github.com/users/arvoelke/repos",
      "events_url": "https://api.github.com/users/arvoelke/events{/privacy}",
      "received_events_url": "https://api.github.com/users/arvoelke/received_events",
      "type": "User",
      "site_admin": false
    },
    "created_at": "2019-04-04T20:01:49Z",
    "updated_at": "2019-04-04T20:01:49Z",
    "author_association": "NONE",
    "body": "Found #4283 which was fixed by #4284. Upgrading from `notebook==5.6.0` to `notebook==5.7.8` fixed the issue for me.",
    "performed_via_github_app": null
  },
  {
    "url": "https://api.github.com/repos/jupyter/notebook/issues/comments/481814557",
    "html_url": "https://github.com/jupyter/notebook/issues/2416#issuecomment-481814557",
    "issue_url": "https://api.github.com/repos/jupyter/notebook/issues/2416",
    "id": 481814557,
    "node_id": "MDEyOklzc3VlQ29tbWVudDQ4MTgxNDU1Nw==",
    "user": {
      "login": "thangleiter",
      "id": 32895729,
      "node_id": "MDQ6VXNlcjMyODk1NzI5",
      "avatar_url": "https://avatars.githubusercontent.com/u/32895729?v=4",
      "gravatar_id": "",
      "url": "https://api.github.com/users/thangleiter",
      "html_url": "https://github.com/thangleiter",
      "followers_url": "https://api.github.com/users/thangleiter/followers",
      "following_url": "https://api.github.com/users/thangleiter/following{/other_user}",
      "gists_url": "https://api.github.com/users/thangleiter/gists{/gist_id}",
      "starred_url": "https://api.github.com/users/thangleiter/starred{/owner}{/repo}",
      "subscriptions_url": "https://api.github.com/users/thangleiter/subscriptions",
      "organizations_url": "https://api.github.com/users/thangleiter/orgs",
      "repos_url": "https://api.github.com/users/thangleiter/repos",
      "events_url": "https://api.github.com/users/thangleiter/events{/privacy}",
      "received_events_url": "https://api.github.com/users/thangleiter/received_events",
      "type": "User",
      "site_admin": false
    },
    "created_at": "2019-04-10T18:44:48Z",
    "updated_at": "2019-04-10T18:44:48Z",
    "author_association": "NONE",
    "body": "> \r\n> \r\n> Found #4283 which was fixed by #4284. Upgrading from `notebook==5.6.0` to `notebook==5.7.8` fixed the issue for me.\r\n\r\nIndeed, the upgrade fixes it. Unfortunately, `notebook==5.7.4` (where the patch was introduced) is incompatible with Python 3.5 and thus one is stuck with the buggy version on Python 3.5.\r\n",
    "performed_via_github_app": null
  },
  {
    "url": "https://api.github.com/repos/jupyter/notebook/issues/comments/482223616",
    "html_url": "https://github.com/jupyter/notebook/issues/2416#issuecomment-482223616",
    "issue_url": "https://api.github.com/repos/jupyter/notebook/issues/2416",
    "id": 482223616,
    "node_id": "MDEyOklzc3VlQ29tbWVudDQ4MjIyMzYxNg==",
    "user": {
      "login": "takluyver",
      "id": 327925,
      "node_id": "MDQ6VXNlcjMyNzkyNQ==",
      "avatar_url": "https://avatars.githubusercontent.com/u/327925?v=4",
      "gravatar_id": "",
      "url": "https://api.github.com/users/takluyver",
      "html_url": "https://github.com/takluyver",
      "followers_url": "https://api.github.com/users/takluyver/followers",
      "following_url": "https://api.github.com/users/takluyver/following{/other_user}",
      "gists_url": "https://api.github.com/users/takluyver/gists{/gist_id}",
      "starred_url": "https://api.github.com/users/takluyver/starred{/owner}{/repo}",
      "subscriptions_url": "https://api.github.com/users/takluyver/subscriptions",
      "organizations_url": "https://api.github.com/users/takluyver/orgs",
      "repos_url": "https://api.github.com/users/takluyver/repos",
      "events_url": "https://api.github.com/users/takluyver/events{/privacy}",
      "received_events_url": "https://api.github.com/users/takluyver/received_events",
      "type": "User",
      "site_admin": false
    },
    "created_at": "2019-04-11T17:47:58Z",
    "updated_at": "2019-04-11T17:47:58Z",
    "author_association": "MEMBER",
    "body": "The 5.7 series should still be supporting 3.5, so if you can see what's making it incompatible, please send a pull request to fix it.",
    "performed_via_github_app": null
  },
  {
    "url": "https://api.github.com/repos/jupyter/notebook/issues/comments/482461175",
    "html_url": "https://github.com/jupyter/notebook/issues/2416#issuecomment-482461175",
    "issue_url": "https://api.github.com/repos/jupyter/notebook/issues/2416",
    "id": 482461175,
    "node_id": "MDEyOklzc3VlQ29tbWVudDQ4MjQ2MTE3NQ==",
    "user": {
      "login": "thangleiter",
      "id": 32895729,
      "node_id": "MDQ6VXNlcjMyODk1NzI5",
      "avatar_url": "https://avatars.githubusercontent.com/u/32895729?v=4",
      "gravatar_id": "",
      "url": "https://api.github.com/users/thangleiter",
      "html_url": "https://github.com/thangleiter",
      "followers_url": "https://api.github.com/users/thangleiter/followers",
      "following_url": "https://api.github.com/users/thangleiter/following{/other_user}",
      "gists_url": "https://api.github.com/users/thangleiter/gists{/gist_id}",
      "starred_url": "https://api.github.com/users/thangleiter/starred{/owner}{/repo}",
      "subscriptions_url": "https://api.github.com/users/thangleiter/subscriptions",
      "organizations_url": "https://api.github.com/users/thangleiter/orgs",
      "repos_url": "https://api.github.com/users/thangleiter/repos",
      "events_url": "https://api.github.com/users/thangleiter/events{/privacy}",
      "received_events_url": "https://api.github.com/users/thangleiter/received_events",
      "type": "User",
      "site_admin": false
    },
    "created_at": "2019-04-12T06:58:21Z",
    "updated_at": "2019-04-12T06:58:21Z",
    "author_association": "NONE",
    "body": "[As far as I can tell](https://anaconda.org/conda-forge/notebook/files), there are at least no conda packages of the 5.7 series for 3.5. 5.6.0 is the last to have been built for 3.5.\r\n\r\nOf course, if 5.6 is still being updated, I can quickly send a PR since it should only be the one line that needs to be changed.",
    "performed_via_github_app": null
  },
  {
    "url": "https://api.github.com/repos/jupyter/notebook/issues/comments/482505370",
    "html_url": "https://github.com/jupyter/notebook/issues/2416#issuecomment-482505370",
    "issue_url": "https://api.github.com/repos/jupyter/notebook/issues/2416",
    "id": 482505370,
    "node_id": "MDEyOklzc3VlQ29tbWVudDQ4MjUwNTM3MA==",
    "user": {
      "login": "takluyver",
      "id": 327925,
      "node_id": "MDQ6VXNlcjMyNzkyNQ==",
      "avatar_url": "https://avatars.githubusercontent.com/u/327925?v=4",
      "gravatar_id": "",
      "url": "https://api.github.com/users/takluyver",
      "html_url": "https://github.com/takluyver",
      "followers_url": "https://api.github.com/users/takluyver/followers",
      "following_url": "https://api.github.com/users/takluyver/following{/other_user}",
      "gists_url": "https://api.github.com/users/takluyver/gists{/gist_id}",
      "starred_url": "https://api.github.com/users/takluyver/starred{/owner}{/repo}",
      "subscriptions_url": "https://api.github.com/users/takluyver/subscriptions",
      "organizations_url": "https://api.github.com/users/takluyver/orgs",
      "repos_url": "https://api.github.com/users/takluyver/repos",
      "events_url": "https://api.github.com/users/takluyver/events{/privacy}",
      "received_events_url": "https://api.github.com/users/takluyver/received_events",
      "type": "User",
      "site_admin": false
    },
    "created_at": "2019-04-12T09:26:22Z",
    "updated_at": "2019-04-12T09:26:22Z",
    "author_association": "MEMBER",
    "body": "Oh, conda packages. As far as I know, conda has stopped building everything for Python 3.5, and nothing we do in this repo will affect that. You probably need to either build a conda environment with a newer Python, or uninstall the package with conda and install a newer version with pip.",
    "performed_via_github_app": null
  },
  {
    "url": "https://api.github.com/repos/jupyter/notebook/issues/comments/482515844",
    "html_url": "https://github.com/jupyter/notebook/issues/2416#issuecomment-482515844",
    "issue_url": "https://api.github.com/repos/jupyter/notebook/issues/2416",
    "id": 482515844,
    "node_id": "MDEyOklzc3VlQ29tbWVudDQ4MjUxNTg0NA==",
    "user": {
      "login": "thangleiter",
      "id": 32895729,
      "node_id": "MDQ6VXNlcjMyODk1NzI5",
      "avatar_url": "https://avatars.githubusercontent.com/u/32895729?v=4",
      "gravatar_id": "",
      "url": "https://api.github.com/users/thangleiter",
      "html_url": "https://github.com/thangleiter",
      "followers_url": "https://api.github.com/users/thangleiter/followers",
      "following_url": "https://api.github.com/users/thangleiter/following{/other_user}",
      "gists_url": "https://api.github.com/users/thangleiter/gists{/gist_id}",
      "starred_url": "https://api.github.com/users/thangleiter/starred{/owner}{/repo}",
      "subscriptions_url": "https://api.github.com/users/thangleiter/subscriptions",
      "organizations_url": "https://api.github.com/users/thangleiter/orgs",
      "repos_url": "https://api.github.com/users/thangleiter/repos",
      "events_url": "https://api.github.com/users/thangleiter/events{/privacy}",
      "received_events_url": "https://api.github.com/users/thangleiter/received_events",
      "type": "User",
      "site_admin": false
    },
    "created_at": "2019-04-12T09:58:48Z",
    "updated_at": "2019-04-12T09:58:48Z",
    "author_association": "NONE",
    "body": "Right, sorry for the confusion about that. Thanks!",
    "performed_via_github_app": null
  },
  {
    "url": "https://api.github.com/repos/jupyter/notebook/issues/comments/571622886",
    "html_url": "https://github.com/jupyter/notebook/issues/2416#issuecomment-571622886",
    "issue_url": "https://api.github.com/repos/jupyter/notebook/issues/2416",
    "id": 571622886,
    "node_id": "MDEyOklzc3VlQ29tbWVudDU3MTYyMjg4Ng==",
    "user": {
      "login": "despoisj",
      "id": 7230845,
      "node_id": "MDQ6VXNlcjcyMzA4NDU=",
      "avatar_url": "https://avatars.githubusercontent.com/u/7230845?v=4",
      "gravatar_id": "",
      "url": "https://api.github.com/users/despoisj",
      "html_url": "https://github.com/despoisj",
      "followers_url": "https://api.github.com/users/despoisj/followers",
      "following_url": "https://api.github.com/users/despoisj/following{/other_user}",
      "gists_url": "https://api.github.com/users/despoisj/gists{/gist_id}",
      "starred_url": "https://api.github.com/users/despoisj/starred{/owner}{/repo}",
      "subscriptions_url": "https://api.github.com/users/despoisj/subscriptions",
      "organizations_url": "https://api.github.com/users/despoisj/orgs",
      "repos_url": "https://api.github.com/users/despoisj/repos",
      "events_url": "https://api.github.com/users/despoisj/events{/privacy}",
      "received_events_url": "https://api.github.com/users/despoisj/received_events",
      "type": "User",
      "site_admin": false
    },
    "created_at": "2020-01-07T14:59:53Z",
    "updated_at": "2020-01-07T14:59:53Z",
    "author_association": "NONE",
    "body": "I don't know why, but I solved this exact issue by upgrading from python 3.6 to python 3.7 (the other suggested fix didn't work).",
    "performed_via_github_app": null
  },
  {
    "url": "https://api.github.com/repos/jupyter/notebook/issues/comments/576373517",
    "html_url": "https://github.com/jupyter/notebook/issues/2416#issuecomment-576373517",
    "issue_url": "https://api.github.com/repos/jupyter/notebook/issues/2416",
    "id": 576373517,
    "node_id": "MDEyOklzc3VlQ29tbWVudDU3NjM3MzUxNw==",
    "user": {
      "login": "alexchernykh",
      "id": 9820604,
      "node_id": "MDQ6VXNlcjk4MjA2MDQ=",
      "avatar_url": "https://avatars.githubusercontent.com/u/9820604?v=4",
      "gravatar_id": "",
      "url": "https://api.github.com/users/alexchernykh",
      "html_url": "https://github.com/alexchernykh",
      "followers_url": "https://api.github.com/users/alexchernykh/followers",
      "following_url": "https://api.github.com/users/alexchernykh/following{/other_user}",
      "gists_url": "https://api.github.com/users/alexchernykh/gists{/gist_id}",
      "starred_url": "https://api.github.com/users/alexchernykh/starred{/owner}{/repo}",
      "subscriptions_url": "https://api.github.com/users/alexchernykh/subscriptions",
      "organizations_url": "https://api.github.com/users/alexchernykh/orgs",
      "repos_url": "https://api.github.com/users/alexchernykh/repos",
      "events_url": "https://api.github.com/users/alexchernykh/events{/privacy}",
      "received_events_url": "https://api.github.com/users/alexchernykh/received_events",
      "type": "User",
      "site_admin": false
    },
    "created_at": "2020-01-20T17:39:16Z",
    "updated_at": "2020-01-20T17:41:06Z",
    "author_association": "NONE",
    "body": "as a workaround you can kill the process by its PID \r\nFor example if Jupyter notebook runs on port 8888\r\n`sudo lsof -i tcp:8888`\r\n`kill -9  PID`\r\n\r\nAfter that you can restart your notebook and the kernel should not die immediately after it starts.",
    "performed_via_github_app": null
  },
  {
    "url": "https://api.github.com/repos/jupyter/notebook/issues/comments/578432397",
    "html_url": "https://github.com/jupyter/notebook/issues/2416#issuecomment-578432397",
    "issue_url": "https://api.github.com/repos/jupyter/notebook/issues/2416",
    "id": 578432397,
    "node_id": "MDEyOklzc3VlQ29tbWVudDU3ODQzMjM5Nw==",
    "user": {
      "login": "Aiiiiii",
      "id": 14947715,
      "node_id": "MDQ6VXNlcjE0OTQ3NzE1",
      "avatar_url": "https://avatars.githubusercontent.com/u/14947715?v=4",
      "gravatar_id": "",
      "url": "https://api.github.com/users/Aiiiiii",
      "html_url": "https://github.com/Aiiiiii",
      "followers_url": "https://api.github.com/users/Aiiiiii/followers",
      "following_url": "https://api.github.com/users/Aiiiiii/following{/other_user}",
      "gists_url": "https://api.github.com/users/Aiiiiii/gists{/gist_id}",
      "starred_url": "https://api.github.com/users/Aiiiiii/starred{/owner}{/repo}",
      "subscriptions_url": "https://api.github.com/users/Aiiiiii/subscriptions",
      "organizations_url": "https://api.github.com/users/Aiiiiii/orgs",
      "repos_url": "https://api.github.com/users/Aiiiiii/repos",
      "events_url": "https://api.github.com/users/Aiiiiii/events{/privacy}",
      "received_events_url": "https://api.github.com/users/Aiiiiii/received_events",
      "type": "User",
      "site_admin": false
    },
    "created_at": "2020-01-25T18:51:56Z",
    "updated_at": "2020-01-25T18:51:56Z",
    "author_association": "NONE",
    "body": "My python version is 3.7.6 and ipython version is 7.8.0. Same problem and haven't solved yet.",
    "performed_via_github_app": null
  },
  {
    "url": "https://api.github.com/repos/jupyter/notebook/issues/comments/584642787",
    "html_url": "https://github.com/jupyter/notebook/issues/2416#issuecomment-584642787",
    "issue_url": "https://api.github.com/repos/jupyter/notebook/issues/2416",
    "id": 584642787,
    "node_id": "MDEyOklzc3VlQ29tbWVudDU4NDY0Mjc4Nw==",
    "user": {
      "login": "martinehman",
      "id": 9597227,
      "node_id": "MDQ6VXNlcjk1OTcyMjc=",
      "avatar_url": "https://avatars.githubusercontent.com/u/9597227?v=4",
      "gravatar_id": "",
      "url": "https://api.github.com/users/martinehman",
      "html_url": "https://github.com/martinehman",
      "followers_url": "https://api.github.com/users/martinehman/followers",
      "following_url": "https://api.github.com/users/martinehman/following{/other_user}",
      "gists_url": "https://api.github.com/users/martinehman/gists{/gist_id}",
      "starred_url": "https://api.github.com/users/martinehman/starred{/owner}{/repo}",
      "subscriptions_url": "https://api.github.com/users/martinehman/subscriptions",
      "organizations_url": "https://api.github.com/users/martinehman/orgs",
      "repos_url": "https://api.github.com/users/martinehman/repos",
      "events_url": "https://api.github.com/users/martinehman/events{/privacy}",
      "received_events_url": "https://api.github.com/users/martinehman/received_events",
      "type": "User",
      "site_admin": false
    },
    "created_at": "2020-02-11T13:49:39Z",
    "updated_at": "2020-02-11T13:50:15Z",
    "author_association": "NONE",
    "body": "Same issue with Python 3.7.4 (not conda) and notebook==6.0.1 and ipython==7.7.0",
    "performed_via_github_app": null
  },
  {
    "url": "https://api.github.com/repos/jupyter/notebook/issues/comments/634833554",
    "html_url": "https://github.com/jupyter/notebook/issues/2416#issuecomment-634833554",
    "issue_url": "https://api.github.com/repos/jupyter/notebook/issues/2416",
    "id": 634833554,
    "node_id": "MDEyOklzc3VlQ29tbWVudDYzNDgzMzU1NA==",
    "user": {
      "login": "cmdavis4",
      "id": 9903805,
      "node_id": "MDQ6VXNlcjk5MDM4MDU=",
      "avatar_url": "https://avatars.githubusercontent.com/u/9903805?v=4",
      "gravatar_id": "",
      "url": "https://api.github.com/users/cmdavis4",
      "html_url": "https://github.com/cmdavis4",
      "followers_url": "https://api.github.com/users/cmdavis4/followers",
      "following_url": "https://api.github.com/users/cmdavis4/following{/other_user}",
      "gists_url": "https://api.github.com/users/cmdavis4/gists{/gist_id}",
      "starred_url": "https://api.github.com/users/cmdavis4/starred{/owner}{/repo}",
      "subscriptions_url": "https://api.github.com/users/cmdavis4/subscriptions",
      "organizations_url": "https://api.github.com/users/cmdavis4/orgs",
      "repos_url": "https://api.github.com/users/cmdavis4/repos",
      "events_url": "https://api.github.com/users/cmdavis4/events{/privacy}",
      "received_events_url": "https://api.github.com/users/cmdavis4/received_events",
      "type": "User",
      "site_admin": false
    },
    "created_at": "2020-05-27T17:51:46Z",
    "updated_at": "2020-05-27T17:51:46Z",
    "author_association": "NONE",
    "body": "> This is because it was finding .html files as well. I believe this is fixed in the latest commit ( #4137 ) in notebook\\notebookapp.py line 1842 which specifies json files only\r\n\r\nConfirmed that the html files were the issue for me, if you're looking for a quick and dirty fix without changing your python or jupyter versions you can find the directory it's looking in with `jupyter --runtime-dir` and delete the .html files there.",
    "performed_via_github_app": null
  },
  {
    "url": "https://api.github.com/repos/jupyter/notebook/issues/comments/796709886",
    "html_url": "https://github.com/jupyter/notebook/issues/2416#issuecomment-796709886",
    "issue_url": "https://api.github.com/repos/jupyter/notebook/issues/2416",
    "id": 796709886,
    "node_id": "MDEyOklzc3VlQ29tbWVudDc5NjcwOTg4Ng==",
    "user": {
      "login": "mcourteaux",
      "id": 845012,
      "node_id": "MDQ6VXNlcjg0NTAxMg==",
      "avatar_url": "https://avatars.githubusercontent.com/u/845012?v=4",
      "gravatar_id": "",
      "url": "https://api.github.com/users/mcourteaux",
      "html_url": "https://github.com/mcourteaux",
      "followers_url": "https://api.github.com/users/mcourteaux/followers",
      "following_url": "https://api.github.com/users/mcourteaux/following{/other_user}",
      "gists_url": "https://api.github.com/users/mcourteaux/gists{/gist_id}",
      "starred_url": "https://api.github.com/users/mcourteaux/starred{/owner}{/repo}",
      "subscriptions_url": "https://api.github.com/users/mcourteaux/subscriptions",
      "organizations_url": "https://api.github.com/users/mcourteaux/orgs",
      "repos_url": "https://api.github.com/users/mcourteaux/repos",
      "events_url": "https://api.github.com/users/mcourteaux/events{/privacy}",
      "received_events_url": "https://api.github.com/users/mcourteaux/received_events",
      "type": "User",
      "site_admin": false
    },
    "created_at": "2021-03-11T12:44:57Z",
    "updated_at": "2021-03-11T12:44:57Z",
    "author_association": "NONE",
    "body": "To get the token for your notebook; just Ctrl-C the process in the terminal, and it will show the token, and ask you to confirm quitting. Just hit \"n\" to keep it running.",
    "performed_via_github_app": null
  }
]
