[
  {
    "url": "https://api.github.com/repos/jupyter/notebook/issues/comments/405430199",
    "html_url": "https://github.com/jupyter/notebook/issues/3734#issuecomment-405430199",
    "issue_url": "https://api.github.com/repos/jupyter/notebook/issues/3734",
    "id": 405430199,
    "node_id": "MDEyOklzc3VlQ29tbWVudDQwNTQzMDE5OQ==",
    "user": {
      "login": "vkumra-broad",
      "id": 30244225,
      "node_id": "MDQ6VXNlcjMwMjQ0MjI1",
      "avatar_url": "https://avatars.githubusercontent.com/u/30244225?v=4",
      "gravatar_id": "",
      "url": "https://api.github.com/users/vkumra-broad",
      "html_url": "https://github.com/vkumra-broad",
      "followers_url": "https://api.github.com/users/vkumra-broad/followers",
      "following_url": "https://api.github.com/users/vkumra-broad/following{/other_user}",
      "gists_url": "https://api.github.com/users/vkumra-broad/gists{/gist_id}",
      "starred_url": "https://api.github.com/users/vkumra-broad/starred{/owner}{/repo}",
      "subscriptions_url": "https://api.github.com/users/vkumra-broad/subscriptions",
      "organizations_url": "https://api.github.com/users/vkumra-broad/orgs",
      "repos_url": "https://api.github.com/users/vkumra-broad/repos",
      "events_url": "https://api.github.com/users/vkumra-broad/events{/privacy}",
      "received_events_url": "https://api.github.com/users/vkumra-broad/received_events",
      "type": "User",
      "site_admin": false
    },
    "created_at": "2018-07-17T01:29:13Z",
    "updated_at": "2018-07-17T01:29:13Z",
    "author_association": "NONE",
    "body": "I am seeing the same error, any idea on what the fix is.\r\n\r\nThanks",
    "performed_via_github_app": null
  },
  {
    "url": "https://api.github.com/repos/jupyter/notebook/issues/comments/430191235",
    "html_url": "https://github.com/jupyter/notebook/issues/3734#issuecomment-430191235",
    "issue_url": "https://api.github.com/repos/jupyter/notebook/issues/3734",
    "id": 430191235,
    "node_id": "MDEyOklzc3VlQ29tbWVudDQzMDE5MTIzNQ==",
    "user": {
      "login": "KKulma",
      "id": 7890048,
      "node_id": "MDQ6VXNlcjc4OTAwNDg=",
      "avatar_url": "https://avatars.githubusercontent.com/u/7890048?v=4",
      "gravatar_id": "",
      "url": "https://api.github.com/users/KKulma",
      "html_url": "https://github.com/KKulma",
      "followers_url": "https://api.github.com/users/KKulma/followers",
      "following_url": "https://api.github.com/users/KKulma/following{/other_user}",
      "gists_url": "https://api.github.com/users/KKulma/gists{/gist_id}",
      "starred_url": "https://api.github.com/users/KKulma/starred{/owner}{/repo}",
      "subscriptions_url": "https://api.github.com/users/KKulma/subscriptions",
      "organizations_url": "https://api.github.com/users/KKulma/orgs",
      "repos_url": "https://api.github.com/users/KKulma/repos",
      "events_url": "https://api.github.com/users/KKulma/events{/privacy}",
      "received_events_url": "https://api.github.com/users/KKulma/received_events",
      "type": "User",
      "site_admin": false
    },
    "created_at": "2018-10-16T10:47:41Z",
    "updated_at": "2018-10-16T10:47:41Z",
    "author_association": "NONE",
    "body": "same here - I get this error when trying to download a feather object. ",
    "performed_via_github_app": null
  }
]
