[
  {
    "url": "https://api.github.com/repos/jupyter/notebook/issues/comments/672892654",
    "html_url": "https://github.com/jupyter/notebook/issues/5674#issuecomment-672892654",
    "issue_url": "https://api.github.com/repos/jupyter/notebook/issues/5674",
    "id": 672892654,
    "node_id": "MDEyOklzc3VlQ29tbWVudDY3Mjg5MjY1NA==",
    "user": {
      "login": "kevin-bates",
      "id": 22599560,
      "node_id": "MDQ6VXNlcjIyNTk5NTYw",
      "avatar_url": "https://avatars.githubusercontent.com/u/22599560?v=4",
      "gravatar_id": "",
      "url": "https://api.github.com/users/kevin-bates",
      "html_url": "https://github.com/kevin-bates",
      "followers_url": "https://api.github.com/users/kevin-bates/followers",
      "following_url": "https://api.github.com/users/kevin-bates/following{/other_user}",
      "gists_url": "https://api.github.com/users/kevin-bates/gists{/gist_id}",
      "starred_url": "https://api.github.com/users/kevin-bates/starred{/owner}{/repo}",
      "subscriptions_url": "https://api.github.com/users/kevin-bates/subscriptions",
      "organizations_url": "https://api.github.com/users/kevin-bates/orgs",
      "repos_url": "https://api.github.com/users/kevin-bates/repos",
      "events_url": "https://api.github.com/users/kevin-bates/events{/privacy}",
      "received_events_url": "https://api.github.com/users/kevin-bates/received_events",
      "type": "User",
      "site_admin": false
    },
    "created_at": "2020-08-12T14:07:06Z",
    "updated_at": "2020-08-12T14:07:06Z",
    "author_association": "MEMBER",
    "body": "Various hits, including #5609, imply an issue with your conda environment.  I would take the advice provided [here](https://github.com/jupyter/notebook/issues/5609#issuecomment-658364606) to try moving forward. ",
    "performed_via_github_app": null
  }
]
