[
  {
    "url": "https://api.github.com/repos/jupyter/notebook/issues/comments/527921637",
    "html_url": "https://github.com/jupyter/notebook/issues/4579#issuecomment-527921637",
    "issue_url": "https://api.github.com/repos/jupyter/notebook/issues/4579",
    "id": 527921637,
    "node_id": "MDEyOklzc3VlQ29tbWVudDUyNzkyMTYzNw==",
    "user": {
      "login": "jeongwookie",
      "id": 25416425,
      "node_id": "MDQ6VXNlcjI1NDE2NDI1",
      "avatar_url": "https://avatars.githubusercontent.com/u/25416425?v=4",
      "gravatar_id": "",
      "url": "https://api.github.com/users/jeongwookie",
      "html_url": "https://github.com/jeongwookie",
      "followers_url": "https://api.github.com/users/jeongwookie/followers",
      "following_url": "https://api.github.com/users/jeongwookie/following{/other_user}",
      "gists_url": "https://api.github.com/users/jeongwookie/gists{/gist_id}",
      "starred_url": "https://api.github.com/users/jeongwookie/starred{/owner}{/repo}",
      "subscriptions_url": "https://api.github.com/users/jeongwookie/subscriptions",
      "organizations_url": "https://api.github.com/users/jeongwookie/orgs",
      "repos_url": "https://api.github.com/users/jeongwookie/repos",
      "events_url": "https://api.github.com/users/jeongwookie/events{/privacy}",
      "received_events_url": "https://api.github.com/users/jeongwookie/received_events",
      "type": "User",
      "site_admin": false
    },
    "created_at": "2019-09-04T14:18:04Z",
    "updated_at": "2019-09-04T14:18:04Z",
    "author_association": "NONE",
    "body": "I have same error.. anyone help?",
    "performed_via_github_app": null
  }
]
