[
  {
    "url": "https://api.github.com/repos/jupyter/notebook/issues/comments/334236340",
    "html_url": "https://github.com/jupyter/notebook/issues/2900#issuecomment-334236340",
    "issue_url": "https://api.github.com/repos/jupyter/notebook/issues/2900",
    "id": 334236340,
    "node_id": "MDEyOklzc3VlQ29tbWVudDMzNDIzNjM0MA==",
    "user": {
      "login": "blink1073",
      "id": 2096628,
      "node_id": "MDQ6VXNlcjIwOTY2Mjg=",
      "avatar_url": "https://avatars.githubusercontent.com/u/2096628?v=4",
      "gravatar_id": "",
      "url": "https://api.github.com/users/blink1073",
      "html_url": "https://github.com/blink1073",
      "followers_url": "https://api.github.com/users/blink1073/followers",
      "following_url": "https://api.github.com/users/blink1073/following{/other_user}",
      "gists_url": "https://api.github.com/users/blink1073/gists{/gist_id}",
      "starred_url": "https://api.github.com/users/blink1073/starred{/owner}{/repo}",
      "subscriptions_url": "https://api.github.com/users/blink1073/subscriptions",
      "organizations_url": "https://api.github.com/users/blink1073/orgs",
      "repos_url": "https://api.github.com/users/blink1073/repos",
      "events_url": "https://api.github.com/users/blink1073/events{/privacy}",
      "received_events_url": "https://api.github.com/users/blink1073/received_events",
      "type": "User",
      "site_admin": false
    },
    "created_at": "2017-10-04T17:49:00Z",
    "updated_at": "2017-10-04T17:49:00Z",
    "author_association": "MEMBER",
    "body": "FWIW I tried with Octave Kernel (a metakernel), and it worked fine for me.\r\n\r\n![image](https://user-images.githubusercontent.com/2096628/31190988-57400416-a902-11e7-93f4-63df468bb676.png)\r\n",
    "performed_via_github_app": null
  },
  {
    "url": "https://api.github.com/repos/jupyter/notebook/issues/comments/334281565",
    "html_url": "https://github.com/jupyter/notebook/issues/2900#issuecomment-334281565",
    "issue_url": "https://api.github.com/repos/jupyter/notebook/issues/2900",
    "id": 334281565,
    "node_id": "MDEyOklzc3VlQ29tbWVudDMzNDI4MTU2NQ==",
    "user": {
      "login": "minrk",
      "id": 151929,
      "node_id": "MDQ6VXNlcjE1MTkyOQ==",
      "avatar_url": "https://avatars.githubusercontent.com/u/151929?v=4",
      "gravatar_id": "",
      "url": "https://api.github.com/users/minrk",
      "html_url": "https://github.com/minrk",
      "followers_url": "https://api.github.com/users/minrk/followers",
      "following_url": "https://api.github.com/users/minrk/following{/other_user}",
      "gists_url": "https://api.github.com/users/minrk/gists{/gist_id}",
      "starred_url": "https://api.github.com/users/minrk/starred{/owner}{/repo}",
      "subscriptions_url": "https://api.github.com/users/minrk/subscriptions",
      "organizations_url": "https://api.github.com/users/minrk/orgs",
      "repos_url": "https://api.github.com/users/minrk/repos",
      "events_url": "https://api.github.com/users/minrk/events{/privacy}",
      "received_events_url": "https://api.github.com/users/minrk/received_events",
      "type": "User",
      "site_admin": false
    },
    "created_at": "2017-10-04T20:35:49Z",
    "updated_at": "2017-10-04T20:35:49Z",
    "author_association": "MEMBER",
    "body": "What prompted the restart? Is there a chance that the kernel had died? Did they perhaps request restart multiple times in quick succession?\r\n\r\nHunch without looking at the code: kernel could have died and the session been deleted, then restart could raise KeyError (though I would expect a 404).",
    "performed_via_github_app": null
  },
  {
    "url": "https://api.github.com/repos/jupyter/notebook/issues/comments/335083137",
    "html_url": "https://github.com/jupyter/notebook/issues/2900#issuecomment-335083137",
    "issue_url": "https://api.github.com/repos/jupyter/notebook/issues/2900",
    "id": 335083137,
    "node_id": "MDEyOklzc3VlQ29tbWVudDMzNTA4MzEzNw==",
    "user": {
      "login": "danielkza",
      "id": 747342,
      "node_id": "MDQ6VXNlcjc0NzM0Mg==",
      "avatar_url": "https://avatars.githubusercontent.com/u/747342?v=4",
      "gravatar_id": "",
      "url": "https://api.github.com/users/danielkza",
      "html_url": "https://github.com/danielkza",
      "followers_url": "https://api.github.com/users/danielkza/followers",
      "following_url": "https://api.github.com/users/danielkza/following{/other_user}",
      "gists_url": "https://api.github.com/users/danielkza/gists{/gist_id}",
      "starred_url": "https://api.github.com/users/danielkza/starred{/owner}{/repo}",
      "subscriptions_url": "https://api.github.com/users/danielkza/subscriptions",
      "organizations_url": "https://api.github.com/users/danielkza/orgs",
      "repos_url": "https://api.github.com/users/danielkza/repos",
      "events_url": "https://api.github.com/users/danielkza/events{/privacy}",
      "received_events_url": "https://api.github.com/users/danielkza/received_events",
      "type": "User",
      "site_admin": false
    },
    "created_at": "2017-10-09T07:31:26Z",
    "updated_at": "2017-10-09T07:31:26Z",
    "author_association": "NONE",
    "body": "Just got the same error when restarting a [jupyter-scala](https://github.com/jupyter-scala) kernel. Similar setup to @parente: Notebook 5.1.0, Python 3.6 from Anaconda 5.0.0.1.",
    "performed_via_github_app": null
  },
  {
    "url": "https://api.github.com/repos/jupyter/notebook/issues/comments/337436102",
    "html_url": "https://github.com/jupyter/notebook/issues/2900#issuecomment-337436102",
    "issue_url": "https://api.github.com/repos/jupyter/notebook/issues/2900",
    "id": 337436102,
    "node_id": "MDEyOklzc3VlQ29tbWVudDMzNzQzNjEwMg==",
    "user": {
      "login": "parente",
      "id": 153745,
      "node_id": "MDQ6VXNlcjE1Mzc0NQ==",
      "avatar_url": "https://avatars.githubusercontent.com/u/153745?v=4",
      "gravatar_id": "",
      "url": "https://api.github.com/users/parente",
      "html_url": "https://github.com/parente",
      "followers_url": "https://api.github.com/users/parente/followers",
      "following_url": "https://api.github.com/users/parente/following{/other_user}",
      "gists_url": "https://api.github.com/users/parente/gists{/gist_id}",
      "starred_url": "https://api.github.com/users/parente/starred{/owner}{/repo}",
      "subscriptions_url": "https://api.github.com/users/parente/subscriptions",
      "organizations_url": "https://api.github.com/users/parente/orgs",
      "repos_url": "https://api.github.com/users/parente/repos",
      "events_url": "https://api.github.com/users/parente/events{/privacy}",
      "received_events_url": "https://api.github.com/users/parente/received_events",
      "type": "User",
      "site_admin": false
    },
    "created_at": "2017-10-18T01:45:17Z",
    "updated_at": "2017-10-18T01:45:17Z",
    "author_association": "MEMBER",
    "body": "> What prompted the restart? Is there a chance that the kernel had died? Did they perhaps request restart multiple times in quick succession?\r\n\r\nFrom the anecdotal evidence I have: kernel was still alive and the user may have done a restart twice in quick succession.\r\n\r\n",
    "performed_via_github_app": null
  },
  {
    "url": "https://api.github.com/repos/jupyter/notebook/issues/comments/420352074",
    "html_url": "https://github.com/jupyter/notebook/issues/2900#issuecomment-420352074",
    "issue_url": "https://api.github.com/repos/jupyter/notebook/issues/2900",
    "id": 420352074,
    "node_id": "MDEyOklzc3VlQ29tbWVudDQyMDM1MjA3NA==",
    "user": {
      "login": "glortho",
      "id": 526284,
      "node_id": "MDQ6VXNlcjUyNjI4NA==",
      "avatar_url": "https://avatars.githubusercontent.com/u/526284?v=4",
      "gravatar_id": "",
      "url": "https://api.github.com/users/glortho",
      "html_url": "https://github.com/glortho",
      "followers_url": "https://api.github.com/users/glortho/followers",
      "following_url": "https://api.github.com/users/glortho/following{/other_user}",
      "gists_url": "https://api.github.com/users/glortho/gists{/gist_id}",
      "starred_url": "https://api.github.com/users/glortho/starred{/owner}{/repo}",
      "subscriptions_url": "https://api.github.com/users/glortho/subscriptions",
      "organizations_url": "https://api.github.com/users/glortho/orgs",
      "repos_url": "https://api.github.com/users/glortho/repos",
      "events_url": "https://api.github.com/users/glortho/events{/privacy}",
      "received_events_url": "https://api.github.com/users/glortho/received_events",
      "type": "User",
      "site_admin": true
    },
    "created_at": "2018-09-11T17:21:28Z",
    "updated_at": "2018-09-11T17:21:28Z",
    "author_association": "NONE",
    "body": "We get this error periodically when first navigating to a new notebook. It will show \"Kernel Error\" with the bomb icon. Logs show this:\r\n```\r\n[E 14:13:17.077 NotebookApp] Uncaught exception POST /notebook/api/sessions (10.255.0.4)\r\n    HTTPServerRequest(protocol='http', host='<our host here>', method='POST', uri='/notebook/api/sessions', version='HTTP/1.1', remote_ip='<our remote ip>')\r\n    Traceback (most recent call last):\r\n      File \"/anaconda/envs/py3/lib/python3.6/site-packages/tornado/web.py\", line 1543, in _execute\r\n        result = yield result\r\n      File \"/anaconda/envs/py3/lib/python3.6/site-packages/tornado/gen.py\", line 1099, in run\r\n        value = future.result()\r\n      File \"/anaconda/envs/py3/lib/python3.6/site-packages/tornado/gen.py\", line 1113, in run\r\n        yielded = self.gen.send(value)\r\n      File \"/anaconda/envs/py3/lib/python3.6/site-packages/notebook/services/sessions/handlers.py\", line 67, in post\r\n        model = yield gen.maybe_future(sm.get_session(path=path))\r\n      File \"/anaconda/envs/py3/lib/python3.6/site-packages/notebook/services/sessions/sessionmanager.py\", line 170, in get_session\r\n        return self.row_to_model(row)\r\n      File \"/anaconda/envs/py3/lib/python3.6/site-packages/notebook/services/sessions/sessionmanager.py\", line 209, in row_to_model\r\n        raise KeyError\r\n    KeyError\r\n[W 14:13:17.078 NotebookApp] Unhandled error\r\n```\r\nCompared to a healthy kernel startup log, it appears these lines are missing from this unhealthy kernel log:\r\n```\r\n[D 14:12:53.045 NotebookApp] Starting kernel: ['/anaconda/envs/py3/share/jupyter/kernels/python3/kernel-startup-py3.sh', '-f', '/home/gremlin/.local/share/jupyter/runtime/kernel-9c168b83-dd97-4e44-824c-1fe0eb628874.json']\r\n[D 14:12:53.049 NotebookApp] Connecting to: tcp://127.0.0.1:53463\r\n[D 14:12:53.049 NotebookApp] Connecting to: tcp://127.0.0.1:46064\r\n[I 14:12:53.051 NotebookApp] Kernel started: 9c168b83-dd97-4e44-824c-1fe0eb628874\r\n[D 14:12:53.051 NotebookApp] Kernel args: {'kernel_name': 'python3', 'cwd': '/home/gremlin'}\r\n```\r\nWhen refreshing the page, everything else is back to normal, as if it were a race condition between the sessions POST and the kernel startup lifecycle itself.\r\n\r\nHas anyone seen the same?\r\n\r\nJupyter 5.6.0 on nvidia/cuda:9.0-cudnn7-runtime-ubuntu16.04",
    "performed_via_github_app": null
  },
  {
    "url": "https://api.github.com/repos/jupyter/notebook/issues/comments/489555854",
    "html_url": "https://github.com/jupyter/notebook/issues/2900#issuecomment-489555854",
    "issue_url": "https://api.github.com/repos/jupyter/notebook/issues/2900",
    "id": 489555854,
    "node_id": "MDEyOklzc3VlQ29tbWVudDQ4OTU1NTg1NA==",
    "user": {
      "login": "jni",
      "id": 492549,
      "node_id": "MDQ6VXNlcjQ5MjU0OQ==",
      "avatar_url": "https://avatars.githubusercontent.com/u/492549?v=4",
      "gravatar_id": "",
      "url": "https://api.github.com/users/jni",
      "html_url": "https://github.com/jni",
      "followers_url": "https://api.github.com/users/jni/followers",
      "following_url": "https://api.github.com/users/jni/following{/other_user}",
      "gists_url": "https://api.github.com/users/jni/gists{/gist_id}",
      "starred_url": "https://api.github.com/users/jni/starred{/owner}{/repo}",
      "subscriptions_url": "https://api.github.com/users/jni/subscriptions",
      "organizations_url": "https://api.github.com/users/jni/orgs",
      "repos_url": "https://api.github.com/users/jni/repos",
      "events_url": "https://api.github.com/users/jni/events{/privacy}",
      "received_events_url": "https://api.github.com/users/jni/received_events",
      "type": "User",
      "site_admin": false
    },
    "created_at": "2019-05-06T09:09:29Z",
    "updated_at": "2019-05-06T09:09:29Z",
    "author_association": "NONE",
    "body": "Was this fixed in #4219? It seems like #4209 was a duplicate of this.\r\n\r\nAnyway, just encountered this when launching a Binder notebook at https://github.com/scikit-image/skimage-tutorials. The notebook version there appears to be 5.7.8. Has #4219 made it to that release?",
    "performed_via_github_app": null
  },
  {
    "url": "https://api.github.com/repos/jupyter/notebook/issues/comments/489656375",
    "html_url": "https://github.com/jupyter/notebook/issues/2900#issuecomment-489656375",
    "issue_url": "https://api.github.com/repos/jupyter/notebook/issues/2900",
    "id": 489656375,
    "node_id": "MDEyOklzc3VlQ29tbWVudDQ4OTY1NjM3NQ==",
    "user": {
      "login": "kevin-bates",
      "id": 22599560,
      "node_id": "MDQ6VXNlcjIyNTk5NTYw",
      "avatar_url": "https://avatars.githubusercontent.com/u/22599560?v=4",
      "gravatar_id": "",
      "url": "https://api.github.com/users/kevin-bates",
      "html_url": "https://github.com/kevin-bates",
      "followers_url": "https://api.github.com/users/kevin-bates/followers",
      "following_url": "https://api.github.com/users/kevin-bates/following{/other_user}",
      "gists_url": "https://api.github.com/users/kevin-bates/gists{/gist_id}",
      "starred_url": "https://api.github.com/users/kevin-bates/starred{/owner}{/repo}",
      "subscriptions_url": "https://api.github.com/users/kevin-bates/subscriptions",
      "organizations_url": "https://api.github.com/users/kevin-bates/orgs",
      "repos_url": "https://api.github.com/users/kevin-bates/repos",
      "events_url": "https://api.github.com/users/kevin-bates/events{/privacy}",
      "received_events_url": "https://api.github.com/users/kevin-bates/received_events",
      "type": "User",
      "site_admin": false
    },
    "created_at": "2019-05-06T15:09:23Z",
    "updated_at": "2019-05-06T15:09:23Z",
    "author_association": "MEMBER",
    "body": "Although the fix in #4219 was to accommodate culled kernel behavior, a nicer error message should be produced regardless - which you are not receiving.  Since culling was, I believe, implemented after this issue was created, I do not believe its necessarily a duplicate - especially since it doesn't appear your kernel was culled.\r\n\r\nFWIW, I have confirmed that #4219 is **not** in 5.7.8.",
    "performed_via_github_app": null
  }
]
