[
  {
    "url": "https://api.github.com/repos/jupyter/notebook/issues/comments/585832339",
    "html_url": "https://github.com/jupyter/notebook/issues/5228#issuecomment-585832339",
    "issue_url": "https://api.github.com/repos/jupyter/notebook/issues/5228",
    "id": 585832339,
    "node_id": "MDEyOklzc3VlQ29tbWVudDU4NTgzMjMzOQ==",
    "user": {
      "login": "jasongrout",
      "id": 192614,
      "node_id": "MDQ6VXNlcjE5MjYxNA==",
      "avatar_url": "https://avatars.githubusercontent.com/u/192614?v=4",
      "gravatar_id": "",
      "url": "https://api.github.com/users/jasongrout",
      "html_url": "https://github.com/jasongrout",
      "followers_url": "https://api.github.com/users/jasongrout/followers",
      "following_url": "https://api.github.com/users/jasongrout/following{/other_user}",
      "gists_url": "https://api.github.com/users/jasongrout/gists{/gist_id}",
      "starred_url": "https://api.github.com/users/jasongrout/starred{/owner}{/repo}",
      "subscriptions_url": "https://api.github.com/users/jasongrout/subscriptions",
      "organizations_url": "https://api.github.com/users/jasongrout/orgs",
      "repos_url": "https://api.github.com/users/jasongrout/repos",
      "events_url": "https://api.github.com/users/jasongrout/events{/privacy}",
      "received_events_url": "https://api.github.com/users/jasongrout/received_events",
      "type": "User",
      "site_admin": false
    },
    "created_at": "2020-02-13T16:01:10Z",
    "updated_at": "2020-02-13T16:01:10Z",
    "author_association": "MEMBER",
    "body": "As a guess, it sounds like you may have a notebook with format version 1? If you look inside the notebook file in a text editor, probably at the bottom, it will say what notebook format version it is, like this:\r\n\r\n```\r\n \"nbformat\": 4,\r\n \"nbformat_minor\": 4\r\n```\r\nWhat versions does it say for your file?",
    "performed_via_github_app": null
  },
  {
    "url": "https://api.github.com/repos/jupyter/notebook/issues/comments/589335014",
    "html_url": "https://github.com/jupyter/notebook/issues/5228#issuecomment-589335014",
    "issue_url": "https://api.github.com/repos/jupyter/notebook/issues/5228",
    "id": 589335014,
    "node_id": "MDEyOklzc3VlQ29tbWVudDU4OTMzNTAxNA==",
    "user": {
      "login": "nealoman",
      "id": 56415998,
      "node_id": "MDQ6VXNlcjU2NDE1OTk4",
      "avatar_url": "https://avatars.githubusercontent.com/u/56415998?v=4",
      "gravatar_id": "",
      "url": "https://api.github.com/users/nealoman",
      "html_url": "https://github.com/nealoman",
      "followers_url": "https://api.github.com/users/nealoman/followers",
      "following_url": "https://api.github.com/users/nealoman/following{/other_user}",
      "gists_url": "https://api.github.com/users/nealoman/gists{/gist_id}",
      "starred_url": "https://api.github.com/users/nealoman/starred{/owner}{/repo}",
      "subscriptions_url": "https://api.github.com/users/nealoman/subscriptions",
      "organizations_url": "https://api.github.com/users/nealoman/orgs",
      "repos_url": "https://api.github.com/users/nealoman/repos",
      "events_url": "https://api.github.com/users/nealoman/events{/privacy}",
      "received_events_url": "https://api.github.com/users/nealoman/received_events",
      "type": "User",
      "site_admin": false
    },
    "created_at": "2020-02-20T21:46:47Z",
    "updated_at": "2020-02-20T21:46:47Z",
    "author_association": "NONE",
    "body": "Almost the same error now appearing in our installation for existing notebook files, which were created under the previous release (last Nov release). Old notebook files have \"nbformat_minor\" : 2.\r\n\r\nNot sure of the side-effects of just changing that value to 3, but that will solve the error popup problem.\r\n\r\nAlso getting a similar validation error when trying to create a new (Python 3) notebook now...and it refuses to create a new notebook.",
    "performed_via_github_app": null
  },
  {
    "url": "https://api.github.com/repos/jupyter/notebook/issues/comments/589426528",
    "html_url": "https://github.com/jupyter/notebook/issues/5228#issuecomment-589426528",
    "issue_url": "https://api.github.com/repos/jupyter/notebook/issues/5228",
    "id": 589426528,
    "node_id": "MDEyOklzc3VlQ29tbWVudDU4OTQyNjUyOA==",
    "user": {
      "login": "jasongrout",
      "id": 192614,
      "node_id": "MDQ6VXNlcjE5MjYxNA==",
      "avatar_url": "https://avatars.githubusercontent.com/u/192614?v=4",
      "gravatar_id": "",
      "url": "https://api.github.com/users/jasongrout",
      "html_url": "https://github.com/jasongrout",
      "followers_url": "https://api.github.com/users/jasongrout/followers",
      "following_url": "https://api.github.com/users/jasongrout/following{/other_user}",
      "gists_url": "https://api.github.com/users/jasongrout/gists{/gist_id}",
      "starred_url": "https://api.github.com/users/jasongrout/starred{/owner}{/repo}",
      "subscriptions_url": "https://api.github.com/users/jasongrout/subscriptions",
      "organizations_url": "https://api.github.com/users/jasongrout/orgs",
      "repos_url": "https://api.github.com/users/jasongrout/repos",
      "events_url": "https://api.github.com/users/jasongrout/events{/privacy}",
      "received_events_url": "https://api.github.com/users/jasongrout/received_events",
      "type": "User",
      "site_admin": false
    },
    "created_at": "2020-02-20T23:49:13Z",
    "updated_at": "2020-02-20T23:49:13Z",
    "author_association": "MEMBER",
    "body": "> Old notebook files have \"nbformat_minor\" : 2.\r\n\r\nThe specific error above almost surely refers to the major version, not the minor version. What is \"nbformat\" for you?",
    "performed_via_github_app": null
  },
  {
    "url": "https://api.github.com/repos/jupyter/notebook/issues/comments/589432732",
    "html_url": "https://github.com/jupyter/notebook/issues/5228#issuecomment-589432732",
    "issue_url": "https://api.github.com/repos/jupyter/notebook/issues/5228",
    "id": 589432732,
    "node_id": "MDEyOklzc3VlQ29tbWVudDU4OTQzMjczMg==",
    "user": {
      "login": "nealoman",
      "id": 56415998,
      "node_id": "MDQ6VXNlcjU2NDE1OTk4",
      "avatar_url": "https://avatars.githubusercontent.com/u/56415998?v=4",
      "gravatar_id": "",
      "url": "https://api.github.com/users/nealoman",
      "html_url": "https://github.com/nealoman",
      "followers_url": "https://api.github.com/users/nealoman/followers",
      "following_url": "https://api.github.com/users/nealoman/following{/other_user}",
      "gists_url": "https://api.github.com/users/nealoman/gists{/gist_id}",
      "starred_url": "https://api.github.com/users/nealoman/starred{/owner}{/repo}",
      "subscriptions_url": "https://api.github.com/users/nealoman/subscriptions",
      "organizations_url": "https://api.github.com/users/nealoman/orgs",
      "repos_url": "https://api.github.com/users/nealoman/repos",
      "events_url": "https://api.github.com/users/nealoman/events{/privacy}",
      "received_events_url": "https://api.github.com/users/nealoman/received_events",
      "type": "User",
      "site_admin": false
    },
    "created_at": "2020-02-21T00:03:48Z",
    "updated_at": "2020-02-21T00:03:48Z",
    "author_association": "NONE",
    "body": "Current notebooks, which are throwing the error have \"nbformat\":4",
    "performed_via_github_app": null
  },
  {
    "url": "https://api.github.com/repos/jupyter/notebook/issues/comments/589436567",
    "html_url": "https://github.com/jupyter/notebook/issues/5228#issuecomment-589436567",
    "issue_url": "https://api.github.com/repos/jupyter/notebook/issues/5228",
    "id": 589436567,
    "node_id": "MDEyOklzc3VlQ29tbWVudDU4OTQzNjU2Nw==",
    "user": {
      "login": "nealoman",
      "id": 56415998,
      "node_id": "MDQ6VXNlcjU2NDE1OTk4",
      "avatar_url": "https://avatars.githubusercontent.com/u/56415998?v=4",
      "gravatar_id": "",
      "url": "https://api.github.com/users/nealoman",
      "html_url": "https://github.com/nealoman",
      "followers_url": "https://api.github.com/users/nealoman/followers",
      "following_url": "https://api.github.com/users/nealoman/following{/other_user}",
      "gists_url": "https://api.github.com/users/nealoman/gists{/gist_id}",
      "starred_url": "https://api.github.com/users/nealoman/starred{/owner}{/repo}",
      "subscriptions_url": "https://api.github.com/users/nealoman/subscriptions",
      "organizations_url": "https://api.github.com/users/nealoman/orgs",
      "repos_url": "https://api.github.com/users/nealoman/repos",
      "events_url": "https://api.github.com/users/nealoman/events{/privacy}",
      "received_events_url": "https://api.github.com/users/nealoman/received_events",
      "type": "User",
      "site_admin": false
    },
    "created_at": "2020-02-21T00:16:49Z",
    "updated_at": "2020-02-21T00:16:49Z",
    "author_association": "NONE",
    "body": "The pop-up \"validation failed\" error (so far just annoying, not obstructive) is: \r\nNotebook validation failed: 2 is less than the minimum of 3:\r\n2",
    "performed_via_github_app": null
  },
  {
    "url": "https://api.github.com/repos/jupyter/notebook/issues/comments/589440576",
    "html_url": "https://github.com/jupyter/notebook/issues/5228#issuecomment-589440576",
    "issue_url": "https://api.github.com/repos/jupyter/notebook/issues/5228",
    "id": 589440576,
    "node_id": "MDEyOklzc3VlQ29tbWVudDU4OTQ0MDU3Ng==",
    "user": {
      "login": "jasongrout",
      "id": 192614,
      "node_id": "MDQ6VXNlcjE5MjYxNA==",
      "avatar_url": "https://avatars.githubusercontent.com/u/192614?v=4",
      "gravatar_id": "",
      "url": "https://api.github.com/users/jasongrout",
      "html_url": "https://github.com/jasongrout",
      "followers_url": "https://api.github.com/users/jasongrout/followers",
      "following_url": "https://api.github.com/users/jasongrout/following{/other_user}",
      "gists_url": "https://api.github.com/users/jasongrout/gists{/gist_id}",
      "starred_url": "https://api.github.com/users/jasongrout/starred{/owner}{/repo}",
      "subscriptions_url": "https://api.github.com/users/jasongrout/subscriptions",
      "organizations_url": "https://api.github.com/users/jasongrout/orgs",
      "repos_url": "https://api.github.com/users/jasongrout/repos",
      "events_url": "https://api.github.com/users/jasongrout/events{/privacy}",
      "received_events_url": "https://api.github.com/users/jasongrout/received_events",
      "type": "User",
      "site_admin": false
    },
    "created_at": "2020-02-21T00:31:57Z",
    "updated_at": "2020-02-21T00:31:57Z",
    "author_association": "MEMBER",
    "body": "Can you upload an example notebook that doesn't work? What version of the nbformat package do you have?",
    "performed_via_github_app": null
  },
  {
    "url": "https://api.github.com/repos/jupyter/notebook/issues/comments/589734774",
    "html_url": "https://github.com/jupyter/notebook/issues/5228#issuecomment-589734774",
    "issue_url": "https://api.github.com/repos/jupyter/notebook/issues/5228",
    "id": 589734774,
    "node_id": "MDEyOklzc3VlQ29tbWVudDU4OTczNDc3NA==",
    "user": {
      "login": "nealoman",
      "id": 56415998,
      "node_id": "MDQ6VXNlcjU2NDE1OTk4",
      "avatar_url": "https://avatars.githubusercontent.com/u/56415998?v=4",
      "gravatar_id": "",
      "url": "https://api.github.com/users/nealoman",
      "html_url": "https://github.com/nealoman",
      "followers_url": "https://api.github.com/users/nealoman/followers",
      "following_url": "https://api.github.com/users/nealoman/following{/other_user}",
      "gists_url": "https://api.github.com/users/nealoman/gists{/gist_id}",
      "starred_url": "https://api.github.com/users/nealoman/starred{/owner}{/repo}",
      "subscriptions_url": "https://api.github.com/users/nealoman/subscriptions",
      "organizations_url": "https://api.github.com/users/nealoman/orgs",
      "repos_url": "https://api.github.com/users/nealoman/repos",
      "events_url": "https://api.github.com/users/nealoman/events{/privacy}",
      "received_events_url": "https://api.github.com/users/nealoman/received_events",
      "type": "User",
      "site_admin": false
    },
    "created_at": "2020-02-21T16:43:20Z",
    "updated_at": "2020-02-21T16:43:20Z",
    "author_association": "NONE",
    "body": "Notebook file attached, with the file extension changed to .txt. However, seems that we maybe had some dissonance in some components that didn't get restarted after a conda update. We had reason to reboot our server last night and now everything seems resolved at this point.\r\n[EDA_Karlv1.0.txt](https://github.com/jupyter/notebook/files/4237071/EDA_Karlv1.0.txt)\r\n",
    "performed_via_github_app": null
  },
  {
    "url": "https://api.github.com/repos/jupyter/notebook/issues/comments/589735513",
    "html_url": "https://github.com/jupyter/notebook/issues/5228#issuecomment-589735513",
    "issue_url": "https://api.github.com/repos/jupyter/notebook/issues/5228",
    "id": 589735513,
    "node_id": "MDEyOklzc3VlQ29tbWVudDU4OTczNTUxMw==",
    "user": {
      "login": "nealoman",
      "id": 56415998,
      "node_id": "MDQ6VXNlcjU2NDE1OTk4",
      "avatar_url": "https://avatars.githubusercontent.com/u/56415998?v=4",
      "gravatar_id": "",
      "url": "https://api.github.com/users/nealoman",
      "html_url": "https://github.com/nealoman",
      "followers_url": "https://api.github.com/users/nealoman/followers",
      "following_url": "https://api.github.com/users/nealoman/following{/other_user}",
      "gists_url": "https://api.github.com/users/nealoman/gists{/gist_id}",
      "starred_url": "https://api.github.com/users/nealoman/starred{/owner}{/repo}",
      "subscriptions_url": "https://api.github.com/users/nealoman/subscriptions",
      "organizations_url": "https://api.github.com/users/nealoman/orgs",
      "repos_url": "https://api.github.com/users/nealoman/repos",
      "events_url": "https://api.github.com/users/nealoman/events{/privacy}",
      "received_events_url": "https://api.github.com/users/nealoman/received_events",
      "type": "User",
      "site_admin": false
    },
    "created_at": "2020-02-21T16:44:48Z",
    "updated_at": "2020-02-21T16:44:48Z",
    "author_association": "NONE",
    "body": "To your nbformat version question: nbformat==5.0.4",
    "performed_via_github_app": null
  },
  {
    "url": "https://api.github.com/repos/jupyter/notebook/issues/comments/589830205",
    "html_url": "https://github.com/jupyter/notebook/issues/5228#issuecomment-589830205",
    "issue_url": "https://api.github.com/repos/jupyter/notebook/issues/5228",
    "id": 589830205,
    "node_id": "MDEyOklzc3VlQ29tbWVudDU4OTgzMDIwNQ==",
    "user": {
      "login": "jasongrout",
      "id": 192614,
      "node_id": "MDQ6VXNlcjE5MjYxNA==",
      "avatar_url": "https://avatars.githubusercontent.com/u/192614?v=4",
      "gravatar_id": "",
      "url": "https://api.github.com/users/jasongrout",
      "html_url": "https://github.com/jasongrout",
      "followers_url": "https://api.github.com/users/jasongrout/followers",
      "following_url": "https://api.github.com/users/jasongrout/following{/other_user}",
      "gists_url": "https://api.github.com/users/jasongrout/gists{/gist_id}",
      "starred_url": "https://api.github.com/users/jasongrout/starred{/owner}{/repo}",
      "subscriptions_url": "https://api.github.com/users/jasongrout/subscriptions",
      "organizations_url": "https://api.github.com/users/jasongrout/orgs",
      "repos_url": "https://api.github.com/users/jasongrout/repos",
      "events_url": "https://api.github.com/users/jasongrout/events{/privacy}",
      "received_events_url": "https://api.github.com/users/jasongrout/received_events",
      "type": "User",
      "site_admin": false
    },
    "created_at": "2020-02-21T20:51:59Z",
    "updated_at": "2020-02-21T20:52:06Z",
    "author_association": "MEMBER",
    "body": "\r\n> However, seems that we maybe had some dissonance in some components that didn't get restarted after a conda update. We had reason to reboot our server last night and now everything seems resolved at this point.\r\n\r\nGreat!\r\n\r\nI looked at the file, and everything seems to be in order there too.",
    "performed_via_github_app": null
  }
]
