[
  {
    "url": "https://api.github.com/repos/jupyter/notebook/issues/comments/464313888",
    "html_url": "https://github.com/jupyter/notebook/issues/4402#issuecomment-464313888",
    "issue_url": "https://api.github.com/repos/jupyter/notebook/issues/4402",
    "id": 464313888,
    "node_id": "MDEyOklzc3VlQ29tbWVudDQ2NDMxMzg4OA==",
    "user": {
      "login": "IamViditAgarwal",
      "id": 43881643,
      "node_id": "MDQ6VXNlcjQzODgxNjQz",
      "avatar_url": "https://avatars.githubusercontent.com/u/43881643?v=4",
      "gravatar_id": "",
      "url": "https://api.github.com/users/IamViditAgarwal",
      "html_url": "https://github.com/IamViditAgarwal",
      "followers_url": "https://api.github.com/users/IamViditAgarwal/followers",
      "following_url": "https://api.github.com/users/IamViditAgarwal/following{/other_user}",
      "gists_url": "https://api.github.com/users/IamViditAgarwal/gists{/gist_id}",
      "starred_url": "https://api.github.com/users/IamViditAgarwal/starred{/owner}{/repo}",
      "subscriptions_url": "https://api.github.com/users/IamViditAgarwal/subscriptions",
      "organizations_url": "https://api.github.com/users/IamViditAgarwal/orgs",
      "repos_url": "https://api.github.com/users/IamViditAgarwal/repos",
      "events_url": "https://api.github.com/users/IamViditAgarwal/events{/privacy}",
      "received_events_url": "https://api.github.com/users/IamViditAgarwal/received_events",
      "type": "User",
      "site_admin": false
    },
    "created_at": "2019-02-16T08:26:18Z",
    "updated_at": "2019-02-16T08:26:18Z",
    "author_association": "NONE",
    "body": "@robotsp  Can u provide more detail log for this error. As by looking at the picture, everything is looking fine. Even the name that u entered is a valid name",
    "performed_via_github_app": null
  }
]
