[
  {
    "url": "https://api.github.com/repos/jupyter/notebook/issues/comments/451915585",
    "html_url": "https://github.com/jupyter/notebook/issues/4320#issuecomment-451915585",
    "issue_url": "https://api.github.com/repos/jupyter/notebook/issues/4320",
    "id": 451915585,
    "node_id": "MDEyOklzc3VlQ29tbWVudDQ1MTkxNTU4NQ==",
    "user": {
      "login": "zlashie",
      "id": 46445274,
      "node_id": "MDQ6VXNlcjQ2NDQ1Mjc0",
      "avatar_url": "https://avatars.githubusercontent.com/u/46445274?v=4",
      "gravatar_id": "",
      "url": "https://api.github.com/users/zlashie",
      "html_url": "https://github.com/zlashie",
      "followers_url": "https://api.github.com/users/zlashie/followers",
      "following_url": "https://api.github.com/users/zlashie/following{/other_user}",
      "gists_url": "https://api.github.com/users/zlashie/gists{/gist_id}",
      "starred_url": "https://api.github.com/users/zlashie/starred{/owner}{/repo}",
      "subscriptions_url": "https://api.github.com/users/zlashie/subscriptions",
      "organizations_url": "https://api.github.com/users/zlashie/orgs",
      "repos_url": "https://api.github.com/users/zlashie/repos",
      "events_url": "https://api.github.com/users/zlashie/events{/privacy}",
      "received_events_url": "https://api.github.com/users/zlashie/received_events",
      "type": "User",
      "site_admin": false
    },
    "created_at": "2019-01-07T12:11:32Z",
    "updated_at": "2019-01-07T12:11:32Z",
    "author_association": "NONE",
    "body": "It appears that it dies specifically to the line \"import numpy as np\" however according to Anaconda Navigator, I do have the library in my environments tab\r\n",
    "performed_via_github_app": null
  },
  {
    "url": "https://api.github.com/repos/jupyter/notebook/issues/comments/451935801",
    "html_url": "https://github.com/jupyter/notebook/issues/4320#issuecomment-451935801",
    "issue_url": "https://api.github.com/repos/jupyter/notebook/issues/4320",
    "id": 451935801,
    "node_id": "MDEyOklzc3VlQ29tbWVudDQ1MTkzNTgwMQ==",
    "user": {
      "login": "jasongrout",
      "id": 192614,
      "node_id": "MDQ6VXNlcjE5MjYxNA==",
      "avatar_url": "https://avatars.githubusercontent.com/u/192614?v=4",
      "gravatar_id": "",
      "url": "https://api.github.com/users/jasongrout",
      "html_url": "https://github.com/jasongrout",
      "followers_url": "https://api.github.com/users/jasongrout/followers",
      "following_url": "https://api.github.com/users/jasongrout/following{/other_user}",
      "gists_url": "https://api.github.com/users/jasongrout/gists{/gist_id}",
      "starred_url": "https://api.github.com/users/jasongrout/starred{/owner}{/repo}",
      "subscriptions_url": "https://api.github.com/users/jasongrout/subscriptions",
      "organizations_url": "https://api.github.com/users/jasongrout/orgs",
      "repos_url": "https://api.github.com/users/jasongrout/repos",
      "events_url": "https://api.github.com/users/jasongrout/events{/privacy}",
      "received_events_url": "https://api.github.com/users/jasongrout/received_events",
      "type": "User",
      "site_admin": false
    },
    "created_at": "2019-01-07T13:33:07Z",
    "updated_at": "2019-01-07T13:33:07Z",
    "author_association": "MEMBER",
    "body": "This looks like a problem with the Anaconda setup, not Jupyter. I'd suggest asking on the Anaconda support channels.\r\n\r\nA short google did turn up this possibly relevant page: https://stackoverflow.com/questions/53026985/the-ordinal-242-could-not-be-located-in-the-dynamic-link-library-anaconda3-libra",
    "performed_via_github_app": null
  },
  {
    "url": "https://api.github.com/repos/jupyter/notebook/issues/comments/451947269",
    "html_url": "https://github.com/jupyter/notebook/issues/4320#issuecomment-451947269",
    "issue_url": "https://api.github.com/repos/jupyter/notebook/issues/4320",
    "id": 451947269,
    "node_id": "MDEyOklzc3VlQ29tbWVudDQ1MTk0NzI2OQ==",
    "user": {
      "login": "zlashie",
      "id": 46445274,
      "node_id": "MDQ6VXNlcjQ2NDQ1Mjc0",
      "avatar_url": "https://avatars.githubusercontent.com/u/46445274?v=4",
      "gravatar_id": "",
      "url": "https://api.github.com/users/zlashie",
      "html_url": "https://github.com/zlashie",
      "followers_url": "https://api.github.com/users/zlashie/followers",
      "following_url": "https://api.github.com/users/zlashie/following{/other_user}",
      "gists_url": "https://api.github.com/users/zlashie/gists{/gist_id}",
      "starred_url": "https://api.github.com/users/zlashie/starred{/owner}{/repo}",
      "subscriptions_url": "https://api.github.com/users/zlashie/subscriptions",
      "organizations_url": "https://api.github.com/users/zlashie/orgs",
      "repos_url": "https://api.github.com/users/zlashie/repos",
      "events_url": "https://api.github.com/users/zlashie/events{/privacy}",
      "received_events_url": "https://api.github.com/users/zlashie/received_events",
      "type": "User",
      "site_admin": false
    },
    "created_at": "2019-01-07T14:14:11Z",
    "updated_at": "2019-01-07T14:14:11Z",
    "author_association": "NONE",
    "body": "> \r\n> \r\n> This looks like a problem with the Anaconda setup, not Jupyter. I'd suggest asking on the Anaconda support channels.\r\n> \r\n> A short google did turn up this possibly relevant page: https://stackoverflow.com/questions/53026985/the-ordinal-242-could-not-be-located-in-the-dynamic-link-library-anaconda3-libra\r\n\r\nHello. I have resolved this issue but a new issue has arised. I installed Python and installed Jupyter Notebook through Python. However, now when I open Jupyter Notebook, I have a \"kernel error\" with \r\n\r\n\"Traceback (most recent call last):\r\n  File \"c:\\users\\ztek\\appdata\\local\\programs\\python\\python37\\lib\\site-packages\\tornado\\web.py\", line 1592, in _execute\r\n    result = yield result\r\n  File \"c:\\users\\ztek\\appdata\\local\\programs\\python\\python37\\lib\\site-packages\\tornado\\gen.py\", line 1133, in run\r\n    value = future.result()\r\n  File \"c:\\users\\ztek\\appdata\\local\\programs\\python\\python37\\lib\\site-packages\\tornado\\gen.py\", line 1141, in run\r\n    yielded = self.gen.throw(*exc_info)\r\n  File \"c:\\users\\ztek\\appdata\\local\\programs\\python\\python37\\lib\\site-packages\\notebook\\services\\sessions\\handlers.py\", line 73, in post\r\n    type=mtype))\r\n  File \"c:\\users\\ztek\\appdata\\local\\programs\\python\\python37\\lib\\site-packages\\tornado\\gen.py\", line 1133, in run\r\n    value = future.result()\r\n  File \"c:\\users\\ztek\\appdata\\local\\programs\\python\\python37\\lib\\site-packages\\tornado\\gen.py\", line 1141, in run\r\n    yielded = self.gen.throw(*exc_info)\r\n  File \"c:\\users\\ztek\\appdata\\local\\programs\\python\\python37\\lib\\site-packages\\notebook\\services\\sessions\\sessionmanager.py\", line 79, in create_session\r\n    kernel_id = yield self.start_kernel_for_session(session_id, path, name, type, kernel_name)\r\n  File \"c:\\users\\ztek\\appdata\\local\\programs\\python\\python37\\lib\\site-packages\\tornado\\gen.py\", line 1133, in run\r\n    value = future.result()\r\n  File \"c:\\users\\ztek\\appdata\\local\\programs\\python\\python37\\lib\\site-packages\\tornado\\gen.py\", line 1141, in run\r\n    yielded = self.gen.throw(*exc_info)\r\n  File \"c:\\users\\ztek\\appdata\\local\\programs\\python\\python37\\lib\\site-packages\\notebook\\services\\sessions\\sessionmanager.py\", line 92, in start_kernel_for_session\r\n    self.kernel_manager.start_kernel(path=kernel_path, kernel_name=kernel_name)\r\n  File \"c:\\users\\ztek\\appdata\\local\\programs\\python\\python37\\lib\\site-packages\\tornado\\gen.py\", line 1133, in run\r\n    value = future.result()\r\n  File \"c:\\users\\ztek\\appdata\\local\\programs\\python\\python37\\lib\\site-packages\\tornado\\gen.py\", line 326, in wrapper\r\n    yielded = next(result)\r\n  File \"c:\\users\\ztek\\appdata\\local\\programs\\python\\python37\\lib\\site-packages\\notebook\\services\\kernels\\kernelmanager.py\", line 160, in start_kernel\r\n    super(MappingKernelManager, self).start_kernel(**kwargs)\r\n  File \"c:\\users\\ztek\\appdata\\local\\programs\\python\\python37\\lib\\site-packages\\jupyter_client\\multikernelmanager.py\", line 110, in start_kernel\r\n    km.start_kernel(**kwargs)\r\n  File \"c:\\users\\ztek\\appdata\\local\\programs\\python\\python37\\lib\\site-packages\\jupyter_client\\manager.py\", line 259, in start_kernel\r\n    **kw)\r\n  File \"c:\\users\\ztek\\appdata\\local\\programs\\python\\python37\\lib\\site-packages\\jupyter_client\\manager.py\", line 204, in _launch_kernel\r\n    return launch_kernel(kernel_cmd, **kw)\r\n  File \"c:\\users\\ztek\\appdata\\local\\programs\\python\\python37\\lib\\site-packages\\jupyter_client\\launcher.py\", line 138, in launch_kernel\r\n    proc = Popen(cmd, **kwargs)\r\n  File \"c:\\users\\ztek\\appdata\\local\\programs\\python\\python37\\lib\\subprocess.py\", line 775, in __init__\r\n    restore_signals, start_new_session)\r\n  File \"c:\\users\\ztek\\appdata\\local\\programs\\python\\python37\\lib\\subprocess.py\", line 1178, in _execute_child\r\n    startupinfo)\r\nFileNotFoundError: [WinError 2] The system cannot find the file spec\"",
    "performed_via_github_app": null
  },
  {
    "url": "https://api.github.com/repos/jupyter/notebook/issues/comments/555039975",
    "html_url": "https://github.com/jupyter/notebook/issues/4320#issuecomment-555039975",
    "issue_url": "https://api.github.com/repos/jupyter/notebook/issues/4320",
    "id": 555039975,
    "node_id": "MDEyOklzc3VlQ29tbWVudDU1NTAzOTk3NQ==",
    "user": {
      "login": "n59e11",
      "id": 25351363,
      "node_id": "MDQ6VXNlcjI1MzUxMzYz",
      "avatar_url": "https://avatars.githubusercontent.com/u/25351363?v=4",
      "gravatar_id": "",
      "url": "https://api.github.com/users/n59e11",
      "html_url": "https://github.com/n59e11",
      "followers_url": "https://api.github.com/users/n59e11/followers",
      "following_url": "https://api.github.com/users/n59e11/following{/other_user}",
      "gists_url": "https://api.github.com/users/n59e11/gists{/gist_id}",
      "starred_url": "https://api.github.com/users/n59e11/starred{/owner}{/repo}",
      "subscriptions_url": "https://api.github.com/users/n59e11/subscriptions",
      "organizations_url": "https://api.github.com/users/n59e11/orgs",
      "repos_url": "https://api.github.com/users/n59e11/repos",
      "events_url": "https://api.github.com/users/n59e11/events{/privacy}",
      "received_events_url": "https://api.github.com/users/n59e11/received_events",
      "type": "User",
      "site_admin": false
    },
    "created_at": "2019-11-18T14:32:15Z",
    "updated_at": "2019-11-18T14:32:15Z",
    "author_association": "NONE",
    "body": "If you resolved the issue, please say something about how, because I came here in search for the same problem as you had. It's a bit sad to find the problem and the \"empty statement\" about having resolved it.",
    "performed_via_github_app": null
  }
]
